Workbook

Sheet AGENDA 
D3: Assunto | E3: Início | F3: Término | G3: Responsável
D5: Mensagem Presidente | E5: 0.375 | F5: 0.38194444 | G5: Rodrigo Demeterco
D6: Resumo EBITDA | E6: 0.38194444 | F6: 0.38541667 | G6: Thiago
D7: Resultados Demercado | E7: 0.38541667 | F7: 0.39236111 | G7: Thiago
D8: Resultados Matriz | E8: 0.39236111 | F8: 0.39930556 | G8: Thiago
D9: Indicadores Financeiros | E9: 0.39930556 | F9: 0.40625 | G9: Thiago
D10: Resultados Condomínios | E10: 0.40625 | F10: 0.42013889 | G10: Rodrigo Habitzreuter
D11: Marketing & IM | E11: 0.42013889 | F11: 0.43402778 | G11: Rodrigo Proença
D12: Engenharia | E12: 0.43402778 | F12: 0.44791667 | G12: Carlos Eduardo/Juliana
D13: Propriedades
D14: Recursos Humanos | E14: 0.44791667 | F14: 0.46180556 | G14: Patricia
D15: TI | E15: 0.46180556 | F15: 0.47569444 | G15: Juliano
D16: Jurídico | E16: 0.47569444 | F16: 0.48958333 | G16: Betina
D19: Assunto | E19: Início | F19: Término | G19: Responsável
D20: Meta Gerência Operações | E20: 0.375 | F20: 0.38194444 | G20: Sérgio
D21: Resultado Hangar Vip | E21: 0.38194444 | F21: 0.39930556 | G21: Sérgio
D22: Resultado Garoto | E22: 0.39930556 | F22: 0.41666667 | G22: Sérgio
D25: Assunto | E25: Início | F25: Término | G25: Responsável
D26: Mensagem Presidente | E26: 0.375 | F26: 0.38194444 | G26: Rodrigo Demeterco
D27: Resumo EBITDA | E27: 0.38194444 | F27: 0.38541667 | G27: Thiago
D28: Resultados Demercado | E28: 0.38541667 | F28: 0.39236111 | G28: Thiago
D29: Resultados Matriz | E29: 0.39236111 | F29: 0.39930556 | G29: Thiago
D30: Indicadores Financeiros | E30: 0.39930556 | F30: 0.40625 | G30: Thiago | J30: 0.40625
D31: Resultados Condomínios | E31: 0.40625 | F31: 0.42013889 | G31: Rodrigo Habitzreuter | J31: 0.42013889
D32: Marketing & IM | E32: 0.42013889 | F32: 0.43402778 | G32: Rodrigo Proença | J32: =J31-J30 -> 0.013888889
D33: Engenharia / Arquitetura | E33: 0.43402778 | F33: 0.44791667 | G33: Ricardo / Juliana
D34: Propriedades | E34: 0.41666667 | F34: 0.43055556 | G34: Cleverson
D35: Recursos Humanos | E35: 0.44791667 | F35: 0.46180556 | G35: Veridiana
D36: TI | E36: 0.46180556 | F36: 0.47569444 | G36: Juliano
D37: Jurídico | E37: 0.47569444 | F37: 0.48958333 | G37: Natália
D43: Assunto | E43: Início | F43: Término | G43: Responsável
D44: Relatório de Auditoria Independente | E44: 0.375 | F44: 0.39583333 | G44: Auditores
D45: Parecer do Conselho Fiscal sobre as DFs | E45: 0.39583333 | F45: 0.40625 | G45: Conselheiros
D46: Apresentação do andamento dos negócios da empresa acumulado Fev/23 | E46: 0.40625 | F46: 0.44791667 | G46: Thiago
D47: Considerações finais | E47: 0.44791667 | F47: 0.46875 | G47: Todos

Sheet Análise Semanal
A2: RITMO SEMANA ANTERIOR
A29: MATRIZ - SEMANA ANTERIOR
A30: REALIZADO/RITMO 2022 | B30: Janeiro | C30: Fevereiro | D30: Março | E30: Abril | F30: Maio | G30: Junho | H30: Julho | I30: Agosto | J30: Setembro | K30: Outubro | L30: Novembro | M30: Dezembro | N30: TOTAL
A31: 1 - FATURAMENTO BRUTO | B31: 4255580.6 | C31: 4255580.6 | D31: 4299728.2 | E31: 4312550.8 | F31: 4405047.6 | G31: 4406354.1 | H31: 4406354.1 | I31: 4414743.2 | J31: 4414777.6 | K31: 4414815.7 | L31: 4476276.8 | M31: 4491045.6 | N31: 52552855
A32: 2 - DEDUÇÃO DE FATURAMENTO | B32: -155328.68 | C32: -155328.68 | D32: -156940.01 | E32: -157408.05 | F32: -160784.31 | G32: -160831.99 | H32: -160831.99 | I32: -161138.22 | J32: -161139.48 | K32: -161140.88 | L32: -163384.2 | M32: -163923.26 | N32: -1918179.8
A33: 3 - FATURAMENTO LIQUIDO | B33: 4100251.9 | C33: 4100251.9 | D33: 4142788.2 | E33: 4155142.7 | F33: 4244263.3 | G33: 4245522.1 | H33: 4245522.1 | I33: 4253604.9 | J33: 4253638.1 | K33: 4253674.9 | L33: 4312892.6 | M33: 4327122.3 | N33: 50634675
A34: 4 - CUSTO MERCADORIA VENDIDA | B34: 0 | C34: 0 | D34: 0 | E34: 0 | F34: 0 | G34: 0 | H34: 0 | I34: 0 | J34: 0 | K34: 0 | L34: 0 | M34: 0 | N34: 0
A35: 5 - LUCRO BRUTO | B35: 4100251.9 | C35: 4100251.9 | D35: 4142788.2 | E35: 4155142.7 | F35: 4244263.3 | G35: 4245522.1 | H35: 4245522.1 | I35: 4253604.9 | J35: 4253638.1 | K35: 4253674.9 | L35: 4312892.6 | M35: 4327122.3 | N35: 50634675
A36: 6 - DESPESAS OPERACIONAIS | B36: -760263.96 | C36: -798744.39 | D36: -781442.35 | E36: -748713.91 | F36: -782460.61 | G36: -969918.35 | H36: -731087.8 | I36: -717953.57 | J36: -758025.34 | K36: -794650.89 | L36: -744417.96 | M36: -772997.37 | N36: -9360676.5
A37: 7 - EBITDA | B37: 3339988 | C37: 3301507.5 | D37: 3361345.8 | E37: 3406428.8 | F37: 3461802.7 | G37: 3275603.8 | H37: 3514434.3 | I37: 3535651.4 | J37: 3495612.8 | K37: 3459024 | L37: 3568474.7 | M37: 3554125 | N37: 41273999
A38: 8 - DEPRECIAÇÃO | B38: -277405.6 | C38: -277405.6 | D38: -277672.27 | E38: -280103.94 | F38: -280120.61 | G38: -280537.28 | H38: -280932.28 | I38: -280932.28 | J38: -280932.28 | K38: -282960.2 | L38: -283585.2 | M38: -288108.12 | N38: -3370695.7
A39: 9 - RESULTADO OPERACIONAL | B39: 3062582.4 | C39: 3024101.9 | D39: 3083673.6 | E39: 3126324.9 | F39: 3181682.1 | G39: 2995066.5 | H39: 3233502 | I39: 3254719.1 | J39: 3214680.5 | K39: 3176063.8 | L39: 3284889.5 | M39: 3266016.8 | N39: 37903303
A40: 10 - OUTRAS RECEITAS E DESPESAS | B40: 64429.04 | C40: 77216.4 | D40: 136348.91 | E40: 169248.96 | F40: 189012.67 | G40: 213302.15 | H40: 223089.23 | I40: 245606.63 | J40: 263720.52 | K40: 264115.61 | L40: 282622.91 | M40: 303474.83 | N40: 2432187.9
A41: 11 - LUCRO ANTES DO IR/CSLL | B41: 3127011.4 | C41: 3101318.3 | D41: 3220022.5 | E41: 3295573.8 | F41: 3370694.8 | G41: 3208368.6 | H41: 3456591.3 | I41: 3500325.7 | J41: 3478401 | K41: 3440179.4 | L41: 3567512.4 | M41: 3569491.7 | N41: 40335491
A42: 12 - IR/CSLL | B42: -585756.86 | C42: -587460.42 | D42: -609724.54 | E42: -619661.52 | F42: -633800.52 | G42: -639556.94 | H42: -640240.39 | I42: -646164.88 | J42: -649683.21 | K42: -647177.54 | L42: -657512.86 | M42: -663565.2 | N42: -7580304.9
A43: 13 - LUCRO LIQUIDO | B43: 2541254.6 | C43: 2513857.9 | D43: 2610297.9 | E43: 2675912.3 | F43: 2736894.3 | G43: 2568811.7 | H43: 2816350.9 | I43: 2854160.8 | J43: 2828717.8 | K43: 2793001.8 | L43: 2909999.5 | M43: 2905926.5 | N43: 32755186
A44: Data atualização | B44: 44568 | N44: 44568
A46: FATURAMENTO BRUTO | F46: CMV | K46: EBITDA
B47: MÊS | C47: ACUMULADO | D47: ANO | E47: Aa | G47: MÊS | H47: ACUMULADO | I47: ANO | L47: MÊS | M47: ACUMULADO | N47: ANO
A48: Semana Anterior | B48: =$B$31 -> 4255580.6 | C48: =SUM($B$31) -> 4255580.6 | D48: =N31 -> 52552855 | E48: =D49-D48 -> 1923233.7 | F48: Semana Anterior | G48: =E34 -> 0 | H48: =SUM(B34:E34) -> 0 | I48: =N34 -> 0 | K48: Semana Anterior | L48: =$B$37 -> 3339988 | M48: =SUM($B$37) -> 3339988 | N48: =N37 -> 41273999 | O48: =N49-N48 -> 2236940.8
A49: Semana atual | B49: ='Matriz senha_capital OK'!$B$34 -> 4291819.8 | C49: =SUM('Matriz senha_capital OK'!$B$34) -> 4291819.8 | D49: ='Matriz senha_capital OK'!N34 -> 54476089 | E49: =B49-B48 -> 36239.23 | F49: Semana atual | G49: 0 | H49: 0 | I49: 0 | K49: Semana atual | L49: ='Matriz senha_capital OK'!$B$40 -> 3442323.9 | M49: =SUM('Matriz senha_capital OK'!$B$40) -> 3442323.9 | N49: ='Matriz senha_capital OK'!N40 -> 43510940 | O49: =L49-L48 -> 102335.94
A50: Variação % | B50: =B49/B48-1 -> 0.0085156958 | C50: =C49/C48-1 -> 0.0085156958 | D50: =D49/D48-1 -> 0.036596179 | F50: Variação % | G50: =G48/G49 -> #DIV/0! | H50: =H48/H49 -> #DIV/0! | I50: =I48/I49 -> #DIV/0! | K50: Variação % | L50: =L49/L48-1 -> 0.030639613 | M50: =M49/M48-1 -> 0.030639613 | N50: =N49/N48-1 -> 0.054197336
A53: LUCRO BRUTO | E53: Aa | F53: DESPESAS OPERACIONAIS
B54: MÊS | C54: ACUMULADO | D54: ANO | G54: MÊS | H54: ACUMULADO | I54: ANO
A55: Semana Anterior | B55: =$B$35 -> 4100251.9 | C55: =SUM($B$35) -> 4100251.9 | D55: =N35 -> 50634675 | E55: =B56-B55 -> 33889.43 | F55: Semana Anterior | G55: =$B$36 -> -760263.96 | H55: =SUM($B$36) -> -760263.96 | I55: =N36 -> -9360676.5 | J55: =I55-I56 -> -391585.53
A56: Semana atual | B56: ='Matriz senha_capital OK'!$B$38 -> 4134141.4 | C56: =SUM('Matriz senha_capital OK'!$B$38) -> 4134141.4 | D56: ='Matriz senha_capital OK'!N38 -> 52480030 | E56: =D55-D56 -> -1845355.2 | F56: Semana atual | G56: ='Matriz senha_capital OK'!$B$39 -> -691817.45 | H56: =SUM('Matriz senha_capital OK'!$B$39) -> -691817.45 | I56: ='Matriz senha_capital OK'!N39 -> -8969091 | J56: =G55-G56 -> -68446.51
A57: Variação % | B57: =B56/B55-1 -> 0.0082652067 | C57: =C56/C55-1 -> 0.0082652067 | D57: =D56/D55-1 -> 0.036444496 | F57: Variação % | G57: =H56/H55-1 -> -0.090029929 | H57: =H56/H55-1 -> -0.090029929 | I57: =I56/I55-1 -> -0.041833037
E59: Aa | F59: RA | G59: Ra
A60: DEMERCADO - SEMANA ANTERIOR
A61: REALIZADO/RITMO 2022 | B61: Janeiro | C61: Fevereiro | D61: Março | E61: Abril | F61: Maio | G61: Junho | H61: Julho | I61: Agosto | J61: Setembro | K61: Outubro | L61: Novembro | M61: Dezembro | N61: TOTAL
A62: 1 - FATURAMENTO BRUTO | B62: 1284468.9 | C62: 1288895.4 | D62: 1289247.8 | E62: 1290182.6 | F62: 1429936.9 | G62: 1492560.6 | H62: 1555184.2 | I62: 1629836.6 | J62: 1693797.1 | K62: 1800656.9 | L62: 1865473.1 | M62: 1865473.1 | N62: 18485713
A63: 2 - DEDUÇÃO DE FATURAMENTO | B63: -118813.36 | C63: -119222.8 | D63: -119255.4 | E63: -119341.85 | F63: -132269.13 | G63: -138061.81 | H63: -143854.49 | I63: -150759.83 | J63: -156676.18 | K63: -166560.7 | L63: -172556.19 | M63: -172556.19 | N63: -1709927.9
A64: 3 - FATURAMENTO LIQUIDO | B64: 1165655.6 | C64: 1169672.6 | D64: 1169992.4 | E64: 1170840.8 | F64: 1297667.8 | G64: 1354498.7 | H64: 1411329.7 | I64: 1479076.7 | J64: 1537121 | K64: 1634096.2 | L64: 1692916.9 | M64: 1692916.9 | N64: 16775785
A65: 4 - CUSTO MERCADORIA VENDIDA | B65: 0 | C65: 0 | D65: 0 | E65: 0 | F65: 0 | G65: 0 | H65: 0 | I65: 0 | J65: 0 | K65: 0 | L65: 0 | M65: 0 | N65: 0
A66: 5 - LUCRO BRUTO | B66: 1165655.6 | C66: 1169672.6 | D66: 1169992.4 | E66: 1170840.8 | F66: 1297667.8 | G66: 1354498.7 | H66: 1411329.7 | I66: 1479076.7 | J66: 1537121 | K66: 1634096.2 | L66: 1692916.9 | M66: 1692916.9 | N66: 16775785
A67: 6 - DESPESAS OPERACIONAIS | B67: -423448.06 | C67: -393887.09 | D67: -432546.68 | E67: -394130.93 | F67: -424913.02 | G67: -586217.81 | H67: -458032.67 | I67: -425691.05 | J67: -417492.77 | K67: -422019.22 | L67: -424719.4 | M67: -403290.58 | N67: -5206389.3
A68: 7 - EBITDA | B68: 742207.5 | C68: 775785.47 | D68: 737445.75 | E68: 776709.83 | F68: 872754.78 | G68: 768280.93 | H68: 953297.01 | I68: 1053385.7 | J68: 1119628.2 | K68: 1212077 | L68: 1268197.5 | M68: 1289626.3 | N68: 11569396
A69: 8 - DEPRECIAÇÃO | B69: -235399.15 | C69: -235399.15 | D69: -235399.15 | E69: -235399.15 | F69: -242136.29 | G69: -242552.96 | H69: -242976.29 | I69: -243392.96 | J69: -243483.21 | K69: -245017.14 | L69: -245017.14 | M69: -245047.14 | N69: -2891219.7
A70: 9 - RESULTADO OPERACIONAL | B70: 506808.35 | C70: 540386.32 | D70: 502046.6 | E70: 541310.68 | F70: 630618.49 | G70: 525727.97 | H70: 710320.72 | I70: 809992.73 | J70: 876144.98 | K70: 967059.85 | L70: 1023180.4 | M70: 1044579.2 | N70: 8678176.2
A71: 10 - OUTRAS RECEITAS E DESPESAS | B71: -581246.23 | C71: -602354.13 | D71: -677847.94 | E71: -711955.81 | F71: -710061.05 | G71: -714313.53 | H71: -714203.38 | I71: -704936.79 | J71: -693403.29 | K71: -676406.29 | L71: -659886.53 | M71: -672632.98 | N71: -8119248
...

Sheet Quadro EBITDA
B2: RITMO
B3: EBITDA (Em R$/Mil) | C3: NOVEMBRO | H3: ACUMULADO JANEIRO A NOVEMBRO | M3: RITMO
C4: Real 2024 | D4: Orç 2025 | E4: Ritmo 2025 | F4: Ritmo 2025 x Orç 2025 | G4: Ritmo 2025 x Real 2024 | H4: Real 2024 | I4: Orç 2025 | J4: Ritmo 2025 | K4: Ritmo 2025 x Orç 2025 | L4: Ritmo 2025 x Real 2024 | M4: Real 2024 | N4: Orç 2025 | O4: Ritmo 2025 | P4: Ritmo 2025 x Orç 2025 | Q4: Ritmo 2025 x Real 2024
B5: Demercado | C5: 1959.1939 | D5: 2065.6617 | E5: 2081.9086 | F5: =(E5/D5-1) -> 0.007865228 | G5: =(E5/C5-1) -> 0.062635286 | H5: 18826.407 | I5: 21831.849 | J5: 22484.974 | K5: =(J5/I5-1) -> 0.029916128 | L5: =(J5/H5-1) -> 0.19433163 | M5: 20743.793 | N5: 23880.127 | O5: 24573.772 | P5: =(O5/N5-1) -> 0.029046974 | Q5: =(O5/M5-1) -> 0.18463253
B6: Capital Realty | C6: 3745.3214 | D6: 3655.6829 | E6: 4138.1043 | F6: =(E6/D6-1) -> 0.13196479 | G6: =(E6/C6-1) -> 0.10487294 | H6: 38194.993 | I6: 37435.673 | J6: 44513.003 | K6: =(J6/I6-1) -> 0.1890531 | L6: =(J6/H6-1) -> 0.16541463 | M6: 40915.713 | N6: 41221.328 | O6: 48685.917 | P6: =(O6/N6-1) -> 0.18108561 | Q6: =(O6/M6-1) -> 0.18990758
B7: Hangar Vip | C7: 75.2033 | D7: 132.52656 | E7: -77.66243 | F7: =(E7/D7-1) -> -1.5860141 | G7: =(E7/C7-1) -> -2.0326998 | H7: 974.56093 | I7: 886.53431 | J7: 940.12334 | K7: =(J7/I7-1) -> 0.060447779 | L7: =(J7/H7-1) -> -0.035336518 | M7: 993.4194 | N7: 1024.6746 | O7: 1043.8898 | P7: =(O7/N7-1) -> 0.018752499 | Q7: =(O7/M7-1) -> 0.050804756
B8: CR Combustíveis | C8: -3.08736 | D8: -3.81875 | E8: 0 | F8: =(E8/D8-1) -> -1 | G8: =(E8/C8-1) -> -1 | H8: -241.31924 | I8: -42.5445 | J8: 151.89878 | K8: =-(J8/I8-1) -> 4.5703506 | L8: =-(J8/H8-1) -> 1.6294516 | M8: -256.31814 | N8: -46.36325 | O8: 151.89878 | P8: =-(O8/N8-1) -> 4.2762755 | Q8: =(O8/M8-1) -> -1.5926181
B9: TOTAL | C9: =SUM(C5:C8) -> 5776.6313 | D9: =SUM(D5:D8) -> 5850.0523 | E9: =SUM(E5:E8) -> 6142.3504 | F9: =E9/D9-1 -> 0.049965037 | G9: =E9/C9-1 -> 0.06331011 | H9: =SUM(H5:H8) -> 57754.642 | I9: =SUM(I5:I8) -> 60111.512 | J9: =SUM(J5:J8) -> 68089.999 | K9: =J9/I9-1 -> 0.1327281 | L9: =J9/H9-1 -> 0.17895284 | M9: =SUM(M5:M8) -> 62396.608 | N9: =SUM(N5:N8) -> 66079.766 | O9: =SUM(O5:O8) -> 74455.478 | P9: =(O9/N9-1) -> 0.12675154 | Q9: =O9/M9-1 -> 0.19326163
B10: Demercado | C10: =C5 -> 1959.1939 | D10: =D5 -> 2065.6617 | E10: =E5 -> 2081.9086 | F10: =(E10/D10-1) -> 0.007865228 | G10: =(E10/C10-1) -> 0.062635286 | H10: =H5 -> 18826.407 | I10: =I5 -> 21831.849 | J10: =J5 -> 22484.974 | K10: =(J10/I10-1) -> 0.029916128 | L10: =(J10/H10-1) -> 0.19433163 | M10: =M5 -> 20743.793 | N10: =N5 -> 23880.127 | O10: =O5 -> 24573.772 | P10: =(O10/N10-1) -> 0.029046974 | Q10: =(O10/M10-1) -> 0.18463253
B11: Margem EBITDA/ROL | C11: =C10/C21 -> 0.81189345 | D11: =D10/D21 -> 0.82522721 | E11: =E10/E21 -> 0.82995533 | F11: =E11-D11 -> 0.004728125 | G11: =E11-C11 -> 0.018061885 | H11: =H5/H21 -> 0.80238679 | I11: =I5/I21 -> 0.81378746 | J11: =J5/J21 -> 0.82642201 | K11: =J11-I11 -> 0.012634551 | L11: =J11-H11 -> 0.024035215 | M11: =M10/M21 -> 0.80228323 | N11: =N10/N21 -> 0.8141497 | O11: =O10/O21 -> 0.82434546 | P11: =O11-N11 -> 0.010195755 | Q11: =O11-M11 -> 0.022062228
B12: Capital Realty | C12: =C6 -> 3745.3214 | D12: =D6 -> 3655.6829 | E12: =E6 -> 4138.1043 | F12: =E12/D12-1 -> 0.13196479 | G12: =E12/C12-1 -> 0.10487294 | H12: =SUM(H6) -> 38194.993 | I12: =SUM(I6) -> 37435.673 | J12: =SUM(J6) -> 44513.003 | K12: =(J12/I12-1) -> 0.1890531 | L12: =(J12/H12-1) -> 0.16541463 | M12: =M6 -> 40915.713 | N12: =N6 -> 41221.328 | O12: =O6 -> 48685.917 | P12: =O12/N12-1 -> 0.18108561 | Q12: =O12/M12-1 -> 0.18990758
B13: Margem EBITDA/ROL | C13: =C12/C22 -> 0.77680827 | D13: =D12/D22 -> 0.77382006 | E13: =E12/E22 -> 0.78942258 | F13: =E13-D13 -> 0.015602521 | G13: =E13-C13 -> 0.012614318 | H13: =H12/H22 -> 0.78858946 | I13: =I12/I22 -> 0.75542693 | J13: =J12/J22 -> 0.80468617 | K13: =J13-I13 -> 0.04925924 | L13: =J13-H13 -> 0.016096707 | M13: =M12/M22 -> 0.77274357 | N13: =N12/N22 -> 0.75574895 | O13: =O12/O22 -> 0.80376435 | P13: =O13-N13 -> 0.048015402 | Q13: =O13-M13 -> 0.031020779
B14: CR Estacionamentos | C14: =(C7) -> 75.2033 | D14: =+D7 -> 132.52656 | E14: =(+E7) -> -77.66243 | F14: =(E14/D14-1) -> -1.5860141 | G14: =(E14/C14-1) -> -2.0326998 | H14: =+H7 -> 974.56093 | I14: =+I7 -> 886.53431 | J14: =J7 -> 940.12334 | K14: =J14/I14-1 -> 0.060447779 | L14: =(J14/H14-1) -> -0.035336518 | M14: =M7-1 -> 992.4194 | N14: =N7-1 -> 1023.6746 | O14: =+O7 -> 1043.8898 | P14: =(O14/N14-1) -> 0.019747691 | Q14: =O14/M14-1 -> 0.051863587
B15: Margem EBITDA/ROL | C15: =C14/C23 -> 0.24987852 | D15: =D14/D23 -> 0.36668824 | E15: =E14/E23 -> -0.19987957 | F15: =E15-D15 -> -0.56656781 | G15: =E15-C15 -> -0.44975809 | H15: =H14/H23 -> 0.29161784 | I15: =I14/I23 -> 0.23933396 | J15: =J14/J23 -> 0.24692748 | K15: =J15-I15 -> 0.007593519 | L15: =J15-H15 -> -0.044690363 | M15: =M14/M23 -> 0.27696557 | N15: =N14/N23 -> 0.25179008 | O15: =O14/O23 -> 0.24919956 | P15: =O15-N15 -> -0.002590522 | Q15: =O15-M15 -> -0.027766009
B16: CR Comércio de Comb | C16: =C8 -> -3.08736 | D16: =D8 -> -3.81875 | E16: =E8 -> 0 | F16: =(E16/D16-1) -> -1 | G16: =(E16/C16-1) -> -1 | H16: =H8 -> -241.31924 | I16: =I8 -> -42.5445 | J16: =J8 -> 151.89878 | K16: =(J16/I16-1) -> -4.5703506 | L16: =((J16/H16)-1) -> -1.6294516 | M16: =M8 -> -256.31814 | N16: =N8 -> -46.36325 | O16: =O8 -> 151.89878 | P16: =(O16/N16-1) -> -4.2762755 | Q16: =(O16/M16-1) -> -1.5926181
B17: Margem EBITDA/ROL | C17: - | D17: - | E17: - | F17: - | G17: - | H17: - | I17: - | J17: - | K17: - | L17: - | M17: - | N17: - | O17: - | P17: - | Q17: -
B20: Faturamento Líquido Ritmo
B21: Demercado | C21: 2413.117 | D21: 2503.143 | E21: 2508.4586 | H21: 23463.008 | I21: 26827.459 | J21: 27207.617 | M21: 25855.948 | N21: 29331.371 | O21: 29810.041
B22: CR Infra | C22: 4821.4232 | D22: 4724.2028 | E22: 5241.9381 | H22: 48434.572 | I22: 49555.651 | J22: 55317.222 | M22: 52948.63 | N22: 54543.679 | O22: 60572.377
B23: CR Estacionamentos | C23: 300.95944 | D23: 361.41481 | E23: 388.54611 | H23: 3341.9112 | I23: 3704.1727 | J23: 3807.2853 | M23: 3583.1869 | N23: 4065.5875 | O23: 4188.9714
B24: CR Comb | C24: 0 | D24: 0 | E24: 0 | H24: 0 | I24: 0 | J24: 0 | M24: 0 | N24: 0 | O24: 0
C25: =SUM(C21:C24) -> 7535.4997 | D25: =SUM(D21:D24) -> 7588.7605 | E25: =SUM(E21:E24) -> 8138.9428 | H25: =SUM(H21:H24) -> 75239.491 | I25: =SUM(I21:I24) -> 80087.283 | J25: =SUM(J21:J24) -> 86332.125 | M25: =SUM(M21:M24) -> 82387.764 | N25: =SUM(N21:N24) -> 87940.637 | O25: =SUM(O21:O24) -> 94571.39
B27: REAL
B29: EBITDA (Em R$/Mil) | C29: JUNHO | H29: ACUMULADO JANEIRO A JUNHO | M29: RITMO
C30: Real 2025 | D30: Orç 2026 | E30: Real 2026 | F30: Real 2026 x Orç 2026 | G30: Real 2026 x Real 2025 | H30: Real 2025 | I30: Orç 2026 | J30: Real 2026 | K30: Real 2026 x Orç 2026 | L30: Real 2026 x Real 2025 | M30: Real 2025 | N30: Orç 2026 | O30: Ritmo 2026 | P30: Ritmo 2026 x Orç 2026 | Q30: Ritmo 2026 x Real 2025
B31: Demercado | C31: ='Quadro DRE Apresentação'!C31 -> 2002.9395 | D31: ='Quadro DRE Apresentação'!D31 -> 2323.1209 | E31: ='Quadro DRE Apresentação'!E31 -> 2210.532 | F31: =(E31/D31-1) -> -0.048464482 | G31: =(E31/C31-1) -> 0.10364393 | H31: ='Quadro DRE Apresentação'!H31 -> 12146.751 | I31: ='Quadro DRE Apresentação'!I31 -> 13654.673 | J31: ='Quadro DRE Apresentação'!J31 -> 13998.193 | K31: =(J31/I31-1) -> 0.025157672 | L31: =(J31/H31-1) -> 0.1524228 | M31: ='Quadro DRE Apresentação'!M31 -> 24854.461 | N31: ='Quadro DRE Apresentação'!N31 -> 28707.954 | O31: ='Quadro DRE Apresentação'!O31 -> 29099.404 | P31: =(O31/N31-1) -> 0.013635598 | Q31: =(O31/M31-1) -> 0.17079198
B32: Margem EBITDA/ROL | C32: =C31/C40 -> 0.81069495 | D32: =D31/D40 -> 0.77704405 | E32: =E31/E40 -> 0.72949153 | F32: =E32-D32 -> -0.04755252 | G32: =E32-C32 -> -0.081203422 | H32: =H31/H40 -> 0.8286848 | I32: =I31/I40 -> 0.79312299 | J32: =J31/J40 -> 0.80282464 | K32: =J32-I32 -> 0.0097016507 | L32: =J32-H32 -> -0.025860156 | M32: =M31/M40 -> 0.83236771 | N32: =N31/N40 -> 0.80819497 | O32: =O31/O40 -> 0.80565598 | P32: =O32-N32 -> -0.0025389944 | Q32: =O32-M32 -> -0.026711736
B33: Capital Realty | C33: ='Quadro DRE Apresentação'!C11 -> 4085.0554 | D33: ='Quadro DRE Apresentação'!D11 -> 4473.0857 | E33: ='Quadro DRE Apresentação'!E11 -> 4974.9488 | F33: =(E33/D33-1) -> 0.11219618 | G33: =(E33/C33-1) -> 0.21784122 | H33: ='Quadro DRE Apresentação'!H11 -> 28475.667 | I33: ='Quadro DRE Apresentação'!I11 -> 30777.921 | J33: ='Quadro DRE Apresentação'!J11 -> 32398.072 | K33: =(J33/I33-1) -> 0.052640053 | L33: =(J33/H33-1) -> 0.13774585 | M33: ='Quadro DRE Apresentação'!M11 -> 49087.274 | N33: ='Quadro DRE Apresentação'!N11 -> 54393.348 | O33: ='Quadro DRE Apresentação'!O11 -> 55712.148 | P33: =(O33/N33-1) -> 0.024245602 | Q33: =(O33/M33-1) -> 0.13496111
B34: Margem EBITDA/ROL | C34: =C33/C41 -> 0.78074961 | D34: =D33/D41 -> 0.81229279 | E34: =E33/E41 -> 0.84275998 | F34: =E34-D34 -> 0.030467199 | G34: =E34-C34 -> 0.062010371 | H34: =H33/H41 -> 0.82592931 | I34: =I33/I41 -> 0.81734218 | J34: =J33/J41 -> 0.84221634 | K34: =J34-I34 -> 0.024874165 | L34: =J34-H34 -> 0.016287035 | M34: =M33/M41 -> 0.81031423 | N34: =N33/N41 -> 0.82623825 | O34: =O33/O41 -> 0.82953568 | P34: =O34-N34 -> 0.0032974335 | Q34: =O34-M34 -> 0.019221452
B35: CR Estacionamentos | C35: ='Quadro DRE Apresentação'!C95 -> 141.44245 | D35: ='Quadro DRE Apresentação'!D95 -> 193.34632 | E35: ='Quadro DRE Apresentação'!E95 -> 260.07537 | F35: =(E35/D35-1) -> 0.34512708 | G35: =(E35/C35-1) -> 0.83873632 | H35: ='Quadro DRE Apresentação'!H95 -> 673.57758 | I35: ='Quadro DRE Apresentação'!I95 -> 746.14484 | J35: ='Quadro DRE Apresentação'!J95 -> 1187.8467 | K35: =(J35/I35-1) -> 0.59197868 | L35: =(J35/H35-1) -> 0.76348904 | M35: ='Quadro DRE Apresentação'!M95 -> 1048.9857 | N35: ='Quadro DRE Apresentação'!N95 -> 1521.582 | O35: ='Quadro DRE Apresentação'!O95 -> 1950.7689 | P35: =((O35/N35)-1) -> 0.28206624 | Q35: =(O35/M35-1) -> 0.85967156
B36: Margem EBITDA/ROL | C36: =C35/C42 -> 0.35268068 | D36: =D35/D42 -> 0.43328752 | E36: =E35/E42 -> 0.54278915 | F36: =E36-D36 -> 0.10950163 | G36: =E36-C36 -> 0.19010847 | H36: =H35/H42 -> 0.29748301 | I36: =I35/I42 -> 0.2834904 | J36: =J35/J42 -> 0.4026773 | K36: =J36-I36 -> 0.1191869 | L36: =J36-H36 -> 0.10519429 | M36: =M35/M42 -> 0.3520488 | N36: =N35/N42 -> 0.38353667 | O36: =O35/O42 -> 0.37829603 | P36: =O36-N36 -> -0.0052406367 | Q36: =O36-M36 -> 0.02624723
B37: TOTAL | C37: =SUM(C31:C35) -> 6231.0288 | D37: =SUM(D31:D35) -> 6991.1422 | E37: =SUM(E31:E35) -> 7447.1285 | F37: =E37/D37-1 -> 0.065223425 | G37: =E37/C37-1 -> 0.19516836 | H37: =SUM(H31:H35) -> 41297.65 | I37: =SUM(I31:I35) -> 45180.349 | J37: =SUM(J31:J35) -> 47585.757 | K37: =J37/I37-1 -> 0.053240128 | L37: =J37/H37-1 -> 0.15226305 | M37: =SUM(M31:M35) -> 74992.364 | N37: =SUM(N31:N35) -> 84624.518 | O37: =SUM(O31:O35) -> 86763.955 | P37: =O37/N37-1 -> 0.02528153 | Q37: =O37/M37-1 -> 0.15697054
B39: Faturamento Líquido Realizado
B40: Demercado | C40: ='Quadro DRE Apresentação'!C27 -> 2470.6451 | D40: ='Quadro DRE Apresentação'!D27 -> 2989.6901 | E40: ='Quadro DRE Apresentação'!E27 -> 3030.2367 | H40: ='Quadro DRE Apresentação'!H27 -> 14657.866 | I40: ='Quadro DRE Apresentação'!I27 -> 17216.337 | J40: ='Quadro DRE Apresentação'!J27 -> 17436.177 | M40: ='Quadro DRE Apresentação'!M27 -> 29859.953 | N40: ='Quadro DRE Apresentação'!N27 -> 35521.074 | O40: ='Quadro DRE Apresentação'!O27 -> 36118.895
B41: CR Infra | C41: ='Quadro DRE Apresentação'!C7 -> 5232.2221 | D41: ='Quadro DRE Apresentação'!D7 -> 5506.7407 | E41: ='Quadro DRE Apresentação'!E7 -> 5903.1622 | H41: ='Quadro DRE Apresentação'!H7 -> 34477.124 | I41: ='Quadro DRE Apresentação'!I7 -> 37656.102 | J41: ='Quadro DRE Apresentação'!J7 -> 38467.636 | M41: ='Quadro DRE Apresentação'!M7 -> 60578.073 | N41: ='Quadro DRE Apresentação'!N7 -> 65832.522 | O41: ='Quadro DRE Apresentação'!O7 -> 67160.64
B42: CR Estacionamento | C42: ='Quadro DRE Apresentação'!C69+'Quadro DRE Apresentação'!C91 -> 401.04961 | D42: ='Quadro DRE Apresentação'!D69+'Quadro DRE Apresentação'!D91 -> 446.23099 | E42: ='Quadro DRE Apresentação'!E69+'Quadro DRE Apresentação'!E91 -> 479.14622 | H42: =+'Quadro DRE Apresentação'!H91 -> 2264.2556 | I42: ='Quadro DRE Apresentação'!I91 -> 2631.9933 | J42: ='Quadro DRE Apresentação'!J91 -> 2949.8725 | M42: ='Quadro DRE Consolidado'!M45 -> 2979.66 | N42: ='Quadro DRE Consolidado'!N45 -> 3967.24 | O42: ='Quadro DRE Apresentação'!O69+'Quadro DRE Apresentação'!O91 -> 5156.7259
B43: CR Comb | C43: 0 | D43: 0 | E43: 0 | H43: ='Quadro DRE Consolidado'!H6 -> 0 | I43: 0 | J43: 0 | M43: ='Quadro DRE Consolidado'!M6 -> 0 | N43: =N24 -> 0 | O43: =O24 -> 0
C44: =SUM(C40:C43) -> 8103.9168 | D44: =SUM(D40:D43) -> 8942.6617 | E44: =SUM(E40:E43) -> 9412.5451 | H44: =SUM(H40:H43) -> 51399.246 | I44: =SUM(I40:I43) -> 57504.433 | J44: =SUM(J40:J43) -> 58853.686 | M44: =SUM(M40:M43) -> 93417.686 | N44: =SUM(N40:N43) -> 105320.84 | O44: =SUM(O40:O43) -> 108436.26
B46: CMV Postos
B47: Posto Esteio | C47: ='Posto Esteio senha_capital OK'!$D$56 -> #REF! | D47: ='Posto Esteio senha_capital OK'!$D$62 -> #REF! | E47: ='Posto Esteio senha_capital OK'!$D$68 -> #REF! | H47: ='Posto Esteio senha_capital OK'!$Q$56 -> #REF! | I47: ='Posto Esteio senha_capital OK'!$Q$62 -> #REF! | J47: ='Posto Esteio senha_capital OK'!$Q$68 -> #REF! | M47: ='Posto Esteio senha_capital OK'!$P$56 -> #REF! | N47: ='Posto Esteio senha_capital OK'!$P$62 -> #REF! | O47: ='Posto Esteio senha_capital OK'!$P$68 -> #REF!
...

Sheet Quadro DRE Apresentação
B3: DRE CAPITAL REALTY (Em R$/Mil) | C3: JULHO | H3: ACUMULADO JANEIRO A JULHO | M3: RITMO
C4: Real 2025 | D4: Orç 2026 | E4: Real 2026 | F4: Real 2026 x Orç 2026 | G4: Real 2026 x Real 2025 | H4: Real 2025 | I4: Orç 2026 | J4: Real 2026 | K4: Real 2026 x Orç 2026 | L4: Real 2026 x Real 2025 | M4: Real 2025 | N4: Orç 2026 | O4: Ritmo 2026 | P4: Ritmo 2026 x Orç 2026 | Q4: Ritmo 2026 x Real 2025
B5: 1 - FATURAMENTO BRUTO | C5: ='Matriz senha_capital OK'!B104/1000 -> 5430.4329 | D5: ='Matriz senha_capital OK'!C104/1000 -> 5715.351 | E5: ='Matriz senha_capital OK'!D104/1000 -> 6126.79 | F5: =IFERROR(E5/D5-1," ") -> 0.071988408 | G5: =IFERROR(E5/C5-1," ") -> 0.12823233 | H5: ='Matriz senha_capital OK'!F104/1000 -> 35942.309 | I5: ='Matriz senha_capital OK'!G104/1000 -> 39082.618 | J5: ='Matriz senha_capital OK'!H104/1000 -> 39924.895 | K5: =IFERROR(J5/I5-1," ") -> 0.021551197 | L5: =IFERROR(J5/H5-1," ") -> 0.11080494 | M5: ='Matriz senha_capital OK'!J104/1000 -> 63033.157 | N5: ='Matriz senha_capital OK'!K104/1000 -> 68326.437 | O5: ='Matriz senha_capital OK'!L104/1000 -> 69704.868 | P5: =IFERROR(O5/N5-1," ") -> 0.020174189 | Q5: =IFERROR(O5/M5-1," ") -> 0.10584447
B6: 2 - DEDUÇÃO DE FATURAMENTO | C6: ='Matriz senha_capital OK'!B105/1000 -> -198.2108 | D6: ='Matriz senha_capital OK'!C105/1000 -> -208.61031 | E6: ='Matriz senha_capital OK'!D105/1000 -> -223.62784 | F6: =IFERROR(E6/D6-1," ") -> 0.071988436 | G6: =IFERROR(E6/C6-1," ") -> 0.12823237 | H6: ='Matriz senha_capital OK'!F105/1000 -> -1465.1856 | I6: ='Matriz senha_capital OK'!G105/1000 -> -1426.5156 | J6: ='Matriz senha_capital OK'!H105/1000 -> -1457.2586 | K6: =IFERROR(J6/I6-1," ") -> 0.021551178 | L6: =IFERROR(J6/H6-1," ") -> -0.0054101884 | M6: ='Matriz senha_capital OK'!J105/1000 -> -2455.084 | N6: ='Matriz senha_capital OK'!K105/1000 -> -2493.915 | O6: ='Matriz senha_capital OK'!L105/1000 -> -2544.2276 | P6: =IFERROR(O6/N6-1," ") -> 0.02017418 | Q6: =IFERROR(O6/M6-1," ") -> 0.036309817
B7: 3 - FATURAMENTO LÍQUIDO | C7: ='Matriz senha_capital OK'!B106/1000 -> 5232.2221 | D7: =D5+D6 -> 5506.7407 | E7: =E5+E6 -> 5903.1622 | F7: =IFERROR(E7/D7-1," ") -> 0.071988407 | G7: =IFERROR(E7/C7-1," ") -> 0.12823233 | H7: ='Matriz senha_capital OK'!F106/1000 -> 34477.124 | I7: =I5+I6 -> 37656.102 | J7: ='Matriz senha_capital OK'!H106/1000 -> 38467.636 | K7: =IFERROR(J7/I7-1," ") -> 0.021551198 | L7: =IFERROR(J7/H7-1," ") -> 0.11574378 | M7: ='Matriz senha_capital OK'!J106/1000 -> 60578.073 | N7: ='Matriz senha_capital OK'!K106/1000 -> 65832.522 | O7: ='Matriz senha_capital OK'!L106/1000 -> 67160.64 | P7: =IFERROR(O7/N7-1," ") -> 0.02017419 | Q7: =IFERROR(O7/M7-1," ") -> 0.10866255
B8: 4 - CUSTO MERCADORIA VENDIDA | C8: ='Matriz senha_capital OK'!B107/1000 -> 0 | D8: ='Matriz senha_capital OK'!C107/1000 -> 0 | E8: ='Matriz senha_capital OK'!D107/1000 -> 0 | F8: 0 | G8: =IFERROR(E8/C8-1," ") | H8: ='Matriz senha_capital OK'!F107/1000 -> -75.10715 | I8: ='Matriz senha_capital OK'!G107/1000 -> 0 | J8: ='Matriz senha_capital OK'!H107/1000 -> 0 | K8: =IFERROR(J8/I8-1," ") | L8: =IFERROR(J8/H8-1," ") -> -1 | M8: -75 | N8: ='Matriz senha_capital OK'!M107/1000 -> 0 | O8: ='Matriz senha_capital OK'!N107/1000 -> 0 | P8: 0 | Q8: =IFERROR(O8/M8-1," ") -> -1
B9: 5 - LUCRO BRUTO | C9: =C7+C8 -> 5232.2221 | D9: =D7+D8 -> 5506.7407 | E9: =E7+E8 -> 5903.1622 | F9: =IFERROR(E9/D9-1," ") -> 0.071988407 | G9: =IFERROR(E9/C9-1," ") -> 0.12823233 | H9: =H7+H8 -> 34402.017 | I9: =I7+I8 -> 37656.102 | J9: ='Matriz senha_capital OK'!H108/1000 -> 38467.636 | K9: =IFERROR(J9/I9-1," ") -> 0.021551198 | L9: =IFERROR(J9/H9-1," ") -> 0.11817969 | M9: =M7+M8 -> 60503.073 | N9: =N7+N8 -> 65832.522 | O9: =O7+O8 -> 67160.64 | P9: =IFERROR(O9/N9-1," ") -> 0.02017419 | Q9: =IFERROR(O9/M9-1," ") -> 0.11003685
B10: 6 - DESPESAS OPERACIONAIS | C10: ='Matriz senha_capital OK'!B109/1000 -> -1147.1667 | D10: ='Matriz senha_capital OK'!C109/1000 -> -1033.655 | E10: ='Matriz senha_capital OK'!D109/1000 -> -928.21331 | F10: =IFERROR(E10/D10-1," ") -> -0.10200855 | G10: =IFERROR(E10/C10-1," ") -> -0.19086451 | H10: ='Matriz senha_capital OK'!F109/1000 -> -5926.3496 | I10: ='Matriz senha_capital OK'!G109/1000 -> -6878.1816 | J10: ='Matriz senha_capital OK'!H109/1000 -> -6069.5643 | K10: =IFERROR(J10/I10-1," ") -> -0.11756265 | L10: =IFERROR(J10/H10-1," ") -> 0.024165749 | M10: ='Matriz senha_capital OK'!J109/1000 -> -11415.798 | N10: ='Matriz senha_capital OK'!K109/1000 -> -11439.174 | O10: ='Matriz senha_capital OK'!L109/1000 -> -11448.493 | P10: =IFERROR(O10/N10-1," ") -> 0.00081459814 | Q10: =IFERROR(O10/M10-1," ") -> 0.0028639583
B11: 7 - EBITDA | C11: =C9+C10 -> 4085.0554 | D11: =D9+D10 -> 4473.0857 | E11: =E9+E10 -> 4974.9488 | F11: =IFERROR(E11/D11-1," ") -> 0.11219618 | G11: =IFERROR(E11/C11-1," ") -> 0.21784122 | H11: =H9+H10 -> 28475.667 | I11: =I9+I10 -> 30777.921 | J11: =J9+J10 -> 32398.072 | K11: =IFERROR(J11/I11-1," ") -> 0.052640053 | L11: =IFERROR(J11/H11-1," ") -> 0.13774585 | M11: =M9+M10 -> 49087.274 | N11: =N9+N10 -> 54393.348 | O11: =O9+O10 -> 55712.148 | P11: =IFERROR(O11/N11-1," ") -> 0.024245602 | Q11: =IFERROR(O11/M11-1," ") -> 0.13496111
B12: 8 - DEPRECIAÇÃO | C12: ='Matriz senha_capital OK'!B111/1000 -> -418.15369 | D12: ='Matriz senha_capital OK'!C111/1000 -> -468.14301 | E12: ='Matriz senha_capital OK'!D111/1000 -> -436.85704 | F12: =IFERROR(E12/D12-1," ") -> -0.066829942 | G12: =IFERROR(E12/C12-1," ") -> 0.044728411 | H12: ='Matriz senha_capital OK'!F111/1000 -> -2118.7395 | I12: ='Matriz senha_capital OK'!G111/1000 -> -3160.5392 | J12: ='Matriz senha_capital OK'!H111/1000 -> -2996.9021 | K12: =IFERROR(J12/I12-1," ") -> -0.051775045 | L12: =IFERROR(J12/H12-1," ") -> 0.41447406 | M12: ='Matriz senha_capital OK'!J111/1000 -> -4218.9355 | N12: ='Matriz senha_capital OK'!K111/1000 -> -5667.3463 | O12: ='Matriz senha_capital OK'!L111/1000 -> -5410.2167 | P12: =IFERROR(O12/N12-1," ") -> -0.045370372 | Q12: =IFERROR(O12/M12-1," ") -> 0.28236533
B13: 9 - RESULTADO OPERACIONAL | C13: =C11+C12 -> 3666.9017 | D13: =D11+D12 -> 4004.9427 | E13: =E11+E12 -> 4538.0918 | F13: =IFERROR(E13/D13-1," ") -> 0.13312278 | G13: =IFERROR(E13/C13-1," ") -> 0.23758207 | H13: =H11+H12 -> 26356.927 | I13: =I11+I12 -> 27617.381 | J13: =J11+J12 -> 29401.17 | K13: =IFERROR(J13/I13-1," ") -> 0.06458934 | L13: =IFERROR(J13/H13-1," ") -> 0.11550066 | M13: =M11+M12 -> 44868.339 | N13: =N11+N12 -> 48726.002 | O13: =O11+O12 -> 50301.931 | P13: =IFERROR(O13/N13-1," ") -> 0.032342672 | Q13: =IFERROR(O13/M13-1," ") -> 0.12110081
B14: 10 - OUTRAS RECEITAS E DESPESAS | C14: =C15+C16 -> 261.44248 | D14: ='Matriz senha_capital OK'!C113/1000 -> 46.67786 | E14: ='Matriz senha_capital OK'!D113/1000 -> 148.46575 | F14: =IFERROR(E14/D14-1," ") -> 2.180646 | G14: =IFERROR(E14/C14-1," ") -> -0.43212844 | H14: =H15+H16 -> 1823.1387 | I14: =I15+I16 -> 325.64952 | J14: =J15+J16 -> 766.17974 | K14: =IFERROR(J14/I14-1," ") -> 1.3527741 | L14: =IFERROR(J14/H14-1," ") -> -0.57974688 | M14: =M16+M15 -> 2687.7722 | N14: =N16+N15 -> 598.75397 | O14: =O16+O15 -> 932.25843 | P14: =IFERROR(O14/N14-1," ") -> 0.55699749 | Q14: =IFERROR(O14/M14-1," ") -> -0.65314827 | S14: 37222.007
B15: 10.1 - RECEITAS FINANCEIRAS | C15: ='Matriz senha_capital OK'!B114/1000 -> 290.21771 | D15: ='Matriz senha_capital OK'!C114/1000 -> 65.4437 | E15: ='Matriz senha_capital OK'!D114/1000 -> 166.96791 | F15: =IFERROR(E15/D15-1," ") -> 1.5513214 | G15: =IFERROR(E15/C15-1," ") -> -0.42468049 | H15: ='Matriz senha_capital OK'!F114/1000 -> 2156.3531 | I15: ='Matriz senha_capital OK'!G114/1000 -> 465.44533 | J15: ='Matriz senha_capital OK'!H114/1000 -> 908.45988 | K15: =IFERROR(J15/I15-1," ") -> 0.95180792 | L15: =IFERROR(J15/H15-1," ") -> -0.57870541 | M15: ='Matriz senha_capital OK'!J114/1000 -> 3135.2433 | N15: ='Matriz senha_capital OK'!K114/1000 -> 825.71263 | O15: ='Matriz senha_capital OK'!L114/1000 -> 1161.7014 | P15: =IFERROR(O15/N15-1," ") -> 0.40690765 | Q15: =IFERROR(O15/M15-1," ") -> -0.62947009 | S15: 382
B16: 10.2 - DESPESAS FINANCEIRAS | C16: ='Matriz senha_capital OK'!B115/1000 -> -28.77523 | D16: ='Matriz senha_capital OK'!C115/1000 -> -18.76584 | E16: ='Matriz senha_capital OK'!D115/1000 -> -18.50216 | F16: =IFERROR(E16/D16-1," ") -> -0.014051063 | G16: =IFERROR(E16/C16-1," ") -> -0.35701087 | H16: ='Matriz senha_capital OK'!F115/1000 -> -333.21435 | I16: ='Matriz senha_capital OK'!G115/1000 -> -139.79581 | J16: ='Matriz senha_capital OK'!H115/1000 -> -142.28014 | K16: =IFERROR(J16/I16-1," ") -> 0.017771133 | L16: =IFERROR(J16/H16-1," ") -> -0.57300716 | M16: ='Matriz senha_capital OK'!J115/1000 -> -447.47111 | N16: ='Matriz senha_capital OK'!K115/1000 -> -226.95866 | O16: ='Matriz senha_capital OK'!L115/1000 -> -229.44299 | P16: =IFERROR(O16/N16-1," ") -> 0.010946178 | Q16: =IFERROR(O16/M16-1," ") -> -0.48724513 | S16: -168
B17: 11 - LUCRO ANTES DO IR/CSLL | C17: =C13+C14 -> 3928.3442 | D17: =D13+D14 -> 4051.6206 | E17: =E13+E14 -> 4686.5576 | F17: =IFERROR(E17/D17-1," ") -> 0.15671186 | G17: =IFERROR(E17/C17-1," ") -> 0.19301093 | H17: =H13+H14 -> 28180.066 | I17: =I13+I14 -> 27943.031 | J17: =J13+J14 -> 30167.35 | K17: =IFERROR(J17/I17-1," ") -> 0.079601911 | L17: =IFERROR(J17/H17-1," ") -> 0.070520893 | M17: =M13+M14 -> 47556.111 | N17: =N13+N14 -> 49324.756 | O17: =O13+O14 -> 51234.189 | P17: =IFERROR(O17/N17-1," ") -> 0.038711465 | Q17: =IFERROR(O17/M17-1," ") -> 0.077341865
B18: 12 - IR/CSLL | C18: ='Matriz senha_capital OK'!B117/1000 -> -687.93352 | D18: ='Matriz senha_capital OK'!C117/1000 -> -705.80683 | E18: ='Matriz senha_capital OK'!D117/1000 -> -774.85172 | F18: =IFERROR(E18/D18-1," ") -> 0.09782406 | G18: =IFERROR(E18/C18-1," ") -> 0.1263468 | H18: ='Matriz senha_capital OK'!F117/1000 -> -4593.4736 | I18: ='Matriz senha_capital OK'!G117/1000 -> -4832.5325 | J18: ='Matriz senha_capital OK'!H117/1000 -> -5025.1317 | K18: =IFERROR(J18/I18-1," ") -> 0.039854701 | L18: =IFERROR(J18/H18-1," ") -> 0.093972028 | M18: ='Matriz senha_capital OK'!J117/1000 -> -7868.4805 | N18: ='Matriz senha_capital OK'!K117/1000 -> -8452.5842 | O18: ='Matriz senha_capital OK'!L117/1000 -> -8672.9185 | P18: =IFERROR(O18/N18-1," ") -> 0.026067095 | Q18: =IFERROR(O18/M18-1," ") -> 0.1022355
B19: 13 - LUCRO LÍQUIDO | C19: =C17+C18 -> 3240.4107 | D19: =D17+D18 -> 3345.8137 | E19: =E17+E18 -> 3911.7058 | F19: =IFERROR(E19/D19-1," ") -> 0.16913437 | G19: =IFERROR(E19/C19-1," ") -> 0.20716361 | H19: =H17+H18 -> 23586.593 | I19: =I17+I18 -> 23110.498 | J19: =J17+J18 -> 25142.218 | K19: =IFERROR(J19/I19-1," ") -> 0.087913271 | L19: =IFERROR(J19/H19-1," ") -> 0.0659538 | M19: =M17+M18 -> 39687.63 | N19: =N17+N18 -> 40872.172 | O19: =O17+O18 -> 42561.271 | P19: =IFERROR(O19/N19-1," ") -> 0.041326388 | Q19: =IFERROR(O19/M19-1," ") -> 0.072406447
B20: Margem EBITDA/ROL | C20: =C11/C7 -> 0.78074961 | D20: =D11/D7 -> 0.81229279 | E20: =E11/E7 -> 0.84275998 | H20: =H11/H7 -> 0.82592931 | I20: =I11/I7 -> 0.81734218 | J20: =J11/J7 -> 0.84221634 | M20: =M11/M7 -> 0.81031423 | N20: =N11/N7 -> 0.82623825 | O20: =O11/O7 -> 0.82953568
B23: DRE DEMERCADO (Em R$/Mil) | C23: =C3 -> JULHO | H23: =H3 -> ACUMULADO JANEIRO A JULHO | M23: =M3 -> RITMO
C24: Real 2025 | D24: Orç 2026 | E24: Real 2026 | F24: Real 2026 x Orç 2026 | G24: Real 2026 x Real 2025 | H24: Real 2025 | I24: Orç 2026 | J24: Real 2026 | K24: Real 2026 x Orç 2026 | L24: Real 2026 x Real 2025 | M24: Real 2025 | N24: Orç 2026 | O24: Ritmo 2026 | P24: Ritmo 2026 x Orç 2026 | Q24: Ritmo 2026 x Real 2025
B25: 1 - FATURAMENTO BRUTO | C25: ='Demercado_senha capital OK'!B110/1000 -> 2564.2398 | D25: ='Demercado_senha capital OK'!C110/1000 -> 3102.9476 | E25: ='Demercado_senha capital OK'!D110/1000 -> 3145.0303 | F25: =IFERROR(E25/D25-1," ") -> 0.013562162 | G25: =IFERROR(E25/C25-1," ") -> 0.22649616 | H25: ='Demercado_senha capital OK'!F110/1000 -> 15234.411 | I25: ='Demercado_senha capital OK'!G110/1000 -> 17868.539 | J25: ='Demercado_senha capital OK'!H110/1000 -> 18096.707 | K25: =IFERROR(J25/I25-1," ") -> 0.012769262 | L25: =IFERROR(J25/H25-1," ") -> 0.1878836 | M25: ='Demercado_senha capital OK'!J110/1000 -> 31012.395 | N25: ='Demercado_senha capital OK'!K110/1000 -> 36865.671 | O25: ='Demercado_senha capital OK'!L110/1000 -> 37487.177 | P25: =IFERROR(O25/N25-1," ") -> 0.01685866 | Q25: =IFERROR(O25/M25-1," ") -> 0.20878047
B26: 2 - DEDUÇÃO DE FATURAMENTO | C26: ='Demercado_senha capital OK'!B111/1000 -> -93.59476 | D26: ='Demercado_senha capital OK'!C111/1000 -> -113.25759 | E26: ='Demercado_senha capital OK'!D111/1000 -> -114.79361 | F26: =IFERROR(E26/D26-1," ") -> 0.013562182 | G26: =IFERROR(E26/C26-1," ") -> 0.22649612 | H26: ='Demercado_senha capital OK'!F111/1000 -> -576.54486 | I26: ='Demercado_senha capital OK'!G111/1000 -> -652.20168 | J26: ='Demercado_senha capital OK'!H111/1000 -> -660.52983 | K26: =IFERROR(J26/I26-1," ") -> 0.012769286 | L26: =IFERROR(J26/H26-1," ") -> 0.14566945 | M26: ='Demercado_senha capital OK'!J111/1000 -> -1152.4413 | N26: ='Demercado_senha capital OK'!K111/1000 -> -1345.597 | O26: ='Demercado_senha capital OK'!L111/1000 -> -1368.282 | P26: =IFERROR(O26/N26-1," ") -> 0.016858673 | Q26: =IFERROR(O26/M26-1," ") -> 0.18728997
B27: 3 - FATURAMENTO LÍQUIDO | C27: =C25+C26 -> 2470.6451 | D27: =D25+D26 -> 2989.6901 | E27: =E25+E26 -> 3030.2367 | F27: =IFERROR(E27/D27-1," ") -> 0.013562162 | G27: =IFERROR(E27/C27-1," ") -> 0.22649616 | H27: =H25+H26 -> 14657.866 | I27: =I25+I26 -> 17216.337 | J27: =J25+J26 -> 17436.177 | K27: =IFERROR(J27/I27-1," ") -> 0.012769261 | L27: =IFERROR(J27/H27-1," ") -> 0.18954403 | M27: ='Demercado_senha capital OK'!J112/1000 -> 29859.953 | N27: ='Demercado_senha capital OK'!K112/1000+1 -> 35521.074 | O27: ='Demercado_senha capital OK'!L112/1000 -> 36118.895 | P27: =IFERROR(O27/N27-1," ") -> 0.016830032 | Q27: =IFERROR(O27/M27-1," ") -> 0.2096099
B28: 4 - CUSTO MERCADORIA VENDIDA | C28: 0 | D28: 0 | E28: 0 | F28: 0 | G28: 0 | H28: 0 | I28: 0 | J28: 0 | K28: 0 | L28: 0 | M28: 0 | N28: 0 | O28: 0 | P28: 0 | Q28: 0
B29: 5 - LUCRO BRUTO | C29: =C27+C28 -> 2470.6451 | D29: =D27+D28 -> 2989.6901 | E29: =E27+E28 -> 3030.2367 | F29: =IFERROR(E29/D29-1," ") -> 0.013562162 | G29: =IFERROR(E29/C29-1," ") -> 0.22649616 | H29: =H27+H28 -> 14657.866 | I29: =I27+I28 -> 17216.337 | J29: =J27+J28 -> 17436.177 | K29: =IFERROR(J29/I29-1," ") -> 0.012769261 | L29: =IFERROR(J29/H29-1," ") -> 0.18954403 | M29: =M27+M28 -> 29859.953 | N29: =N27+N28 -> 35521.074 | O29: =O27+O28 -> 36118.895 | P29: =IFERROR(O29/N29-1," ") -> 0.016830032 | Q29: =IFERROR(O29/M29-1," ") -> 0.2096099
B30: 6 - DESPESAS OPERACIONAIS | C30: ='Demercado_senha capital OK'!B114/1000 -> -467.70558 | D30: ='Demercado_senha capital OK'!C114/1000 -> -666.56918 | E30: ='Demercado_senha capital OK'!D114/1000 -> -819.70469 | F30: =IFERROR(E30/D30-1," ") -> 0.22973686 | G30: =IFERROR(E30/C30-1," ") -> 0.75260832 | H30: ='Demercado_senha capital OK'!F114/1000 -> -2511.1154 | I30: ='Demercado_senha capital OK'!G114/1000 -> -3561.6644 | J30: ='Demercado_senha capital OK'!H114/1000 -> -3437.9845 | K30: =IFERROR(J30/I30-1," ") -> -0.034725304 | L30: =IFERROR(J30/H30-1," ") -> 0.36910658 | M30: ='Demercado_senha capital OK'!J114/1000 -> -5005.4923 | N30: ='Demercado_senha capital OK'!K114/1000 -> -6812.1206 | O30: ='Demercado_senha capital OK'!L114/1000 -> -7019.4914 | P30: =IFERROR(O30/N30-1," ") -> 0.030441432 | Q30: =IFERROR(O30/M30-1," ") -> 0.40235785
B31: 7 - EBITDA | C31: =C29+C30 -> 2002.9395 | D31: =(D29+D30) -> 2323.1209 | E31: =E29+E30 -> 2210.532 | F31: =IFERROR(E31/D31-1," ") -> -0.048464482 | G31: =IFERROR(E31/C31-1," ") -> 0.10364393 | H31: =H29+H30 -> 12146.751 | I31: =I29+I30 -> 13654.673 | J31: =J29+J30 -> 13998.193 | K31: =IFERROR(J31/I31-1," ") -> 0.025157672 | L31: =IFERROR(J31/H31-1," ") -> 0.1524228 | M31: =M29+M30 -> 24854.461 | N31: =N29+N30-1 -> 28707.954 | O31: =O29+O30 -> 29099.404 | P31: =IFERROR(O31/N31-1," ") -> 0.013635598 | Q31: =IFERROR(O31/M31-1," ") -> 0.17079198
B32: 8 - DEPRECIAÇÃO | C32: ='Demercado_senha capital OK'!B116/1000 -> -217.843 | D32: ='Demercado_senha capital OK'!C116/1000 -> -212.08769 | E32: ='Demercado_senha capital OK'!D116/1000 -> -203.12457 | F32: =IFERROR(E32/D32-1," ") -> -0.042261387 | G32: =IFERROR(E32/C32-1," ") -> -0.067564393 | H32: ='Demercado_senha capital OK'!F116/1000 -> -1306.9351 | I32: ='Demercado_senha capital OK'!G116/1000 -> -1267.0218 | J32: ='Demercado_senha capital OK'!H116/1000 -> -1215.231 | K32: =IFERROR(J32/I32-1," ") -> -0.040875974 | L32: =IFERROR(J32/H32-1," ") -> -0.070167264 | M32: ='Demercado_senha capital OK'!J116/1000 -> -2617.5621 | N32: ='Demercado_senha capital OK'!K116/1000 -> -2628.5893 | O32: ='Demercado_senha capital OK'!L116/1000 -> -2566.0396 | P32: =IFERROR(O32/N32-1," ") -> -0.023795908 | Q32: =IFERROR(O32/M32-1," ") -> -0.019683373
B33: 9 - RESULTADO OPERACIONAL | C33: =C31+C32 -> 1785.0965 | D33: =D31+D32 -> 2111.0332 | E33: =E31+E32 -> 2007.4074 | F33: =IFERROR(E33/D33-1," ") -> -0.049087684 | G33: =IFERROR(E33/C33-1," ") -> 0.12453722 | H33: =H31+H32 -> 10839.816 | I33: =I31+I32 -> 12387.651 | J33: =J31+J32 -> 12782.962 | K33: =IFERROR(J33/I33-1," ") -> 0.031911661 | L33: =IFERROR(J33/H33-1," ") -> 0.17926004 | M33: =M31+M32 -> 22236.899 | N33: =N31+N32 -> 26079.364 | O33: =O31+O32 -> 26533.364 | P33: =IFERROR(O33/N33-1," ") -> 0.017408391 | Q33: =IFERROR(O33/M33-1," ") -> 0.19321332
B34: 10 - OUTRAS RECEITAS E DESPESAS | C34: =C36+C35 -> -546.65769 | D34: =D36+D35 -> -717.49463 | E34: =E36+E35 -> -709.34235 | F34: =IFERROR(E34/D34-1," ") -> -0.011362148 | G34: =IFERROR(E34/C34-1," ") -> 0.29759878 | H34: =H36+H35 -> -3350.106 | I34: =I36+I35 -> -4660.7192 | J34: =J36+J35 -> -4402.2158 | K34: =IFERROR(J34/I34-1," ") -> -0.055464275 | L34: =IFERROR(J34/H34-1," ") -> 0.31405268 | M34: =M36+M35 -> -5944.9179 | N34: =N36+N35 -> -8763.7286 | O34: =O36+O35 -> -8253.7532 | P34: =IFERROR(O34/N34-1," ") -> -0.058191595 | Q34: =IFERROR(O34/M34-1," ") -> 0.38837128
B35: 10.1 - RECEITAS FINANCEIRAS | C35: ='Demercado_senha capital OK'!B119/1000 -> 123.79369 | D35: ='Demercado_senha capital OK'!C119/1000 -> 94.3265 | E35: ='Demercado_senha capital OK'!D119/1000 -> 105.35181 | F35: =IFERROR(E35/D35-1," ") -> 0.11688454 | G35: =IFERROR(E35/C35-1," ") -> -0.1489727 | H35: ='Demercado_senha capital OK'!F119/1000 -> 800.84841 | I35: ='Demercado_senha capital OK'!G119/1000 -> 525.6098 | J35: ='Demercado_senha capital OK'!H119/1000 -> 644.16808 | K35: =IFERROR(J35/I35-1," ") -> 0.2255633 | L35: =IFERROR(J35/H35-1," ") -> -0.19564293 | M35: ='Demercado_senha capital OK'!J119/1000 -> 2150.2974 | N35: ='Demercado_senha capital OK'!K119/1000 -> 791.26861 | O35: ='Demercado_senha capital OK'!L119/1000 -> 1330.3212 | P35: =IFERROR(O35/N35-1," ") -> 0.68125102 | Q35: =IFERROR(O35/M35-1," ") -> -0.38133154
B36: 10.2 - DESPESAS FINANCEIRAS | C36: ='Demercado_senha capital OK'!B120/1000 -> -670.45138 | D36: ='Demercado_senha capital OK'!C120/1000 -> -811.82113 | E36: ='Demercado_senha capital OK'!D120/1000 -> -814.69416 | F36: =IFERROR(E36/D36-1," ") -> 0.0035389939 | G36: =IFERROR(E36/C36-1," ") -> 0.21514279 | H36: ='Demercado_senha capital OK'!F120/1000 -> -4150.9544 | I36: ='Demercado_senha capital OK'!G120/1000 -> -5186.329 | J36: ='Demercado_senha capital OK'!H120/1000 -> -5046.3838 | K36: =IFERROR(J36/I36-1," ") -> -0.026983466 | L36: =IFERROR(J36/H36-1," ") -> 0.21571652 | M36: ='Demercado_senha capital OK'!J120/1000 -> -8095.2153 | N36: ='Demercado_senha capital OK'!K120/1000 -> -9554.9972 | O36: ='Demercado_senha capital OK'!L120/1000 -> -9584.0744 | P36: =IFERROR(O36/N36-1," ") -> 0.0030431417 | Q36: =IFERROR(O36/M36-1," ") -> 0.18391841
B37: 11 - LUCRO ANTES DO IR/CSLL | C37: =C33+C34 -> 1238.4388 | D37: =D33+D34 -> 1393.5385 | E37: =E33+E34 -> 1298.0651 | F37: =IFERROR(E37/D37-1," ") -> -0.068511524 | G37: =IFERROR(E37/C37-1," ") -> 0.048146335 | H37: =H33+H34 -> 7489.7099 | I37: =I33+I34 -> 7726.9321 | J37: =J33+J34 -> 8380.746 | K37: =IFERROR(J37/I37-1," ") -> 0.084614946 | L37: =IFERROR(J37/H37-1," ") -> 0.11896804 | M37: =M33+M34 -> 16291.981 | N37: =N33+N34 -> 17315.636 | O37: =O33+O34 -> 18279.611 | P37: =IFERROR(O37/N37-1," ") -> 0.05567079 | Q37: =IFERROR(O37/M37-1," ") -> 0.1220005
B38: 12 - IR/CSLL | C38: ='Demercado_senha capital OK'!B122/1000 -> -322.49868 | D38: ='Demercado_senha capital OK'!C122/1000 -> -403.18356 | E38: ='Demercado_senha capital OK'!D122/1000 -> -412.32707 | F38: =IFERROR(E38/D38-1," ") -> 0.022678281 | G38: =IFERROR(E38/C38-1," ") -> 0.27853878 | H38: ='Demercado_senha capital OK'!F122/1000 -> -1964.5671 | I38: ='Demercado_senha capital OK'!G122/1000 -> -2315.7846 | J38: ='Demercado_senha capital OK'!H122/1000 -> -2340.9835 | K38: =IFERROR(J38/I38-1," ") -> 0.01088137 | L38: =IFERROR(J38/H38-1," ") -> 0.19160272 | M38: ='Demercado_senha capital OK'!J122/1000 -> -4148.4654 | N38: ='Demercado_senha capital OK'!K122/1000 -> -4678.1656 | O38: ='Demercado_senha capital OK'!L122/1000 -> -4893.3758 | P38: =IFERROR(O38/N38-1," ") -> 0.046003102 | Q38: =IFERROR(O38/M38-1," ") -> 0.17956288
B39: 13 - LUCRO LÍQUIDO | C39: =C37+C38 -> 915.94013 | D39: =D37+D38 -> 990.35499 | E39: =E37+E38 -> 885.73803 | F39: =IFERROR(E39/D39-1," ") -> -0.10563582 | G39: =IFERROR(E39/C39-1," ") -> -0.03297388 | H39: =H37+H38 -> 5525.1427 | I39: =I37+I38 -> 5411.1474 | J39: =J37+J38 -> 6039.7625 | K39: =IFERROR(J39/I39-1," ") -> 0.11617038 | L39: =IFERROR(J39/H39-1," ") -> 0.093141434 | M39: =M37+M38 -> 12143.516 | N39: =N37+N38 -> 12637.47 | O39: =O37+O38 -> 13386.235 | P39: =IFERROR(O39/N39-1," ") -> 0.059249596 | Q39: =IFERROR(O39/M39-1," ") -> 0.10233605
B40: Margem EBITDA/ROL | C40: =C31/C27 -> 0.81069495 | D40: =D31/D27 -> 0.77704405 | E40: =E31/E27 -> 0.72949153 | H40: =H31/H27 -> 0.8286848 | I40: =I31/I27 -> 0.79312299 | J40: =J31/J27 -> 0.80282464 | M40: =M31/M27 -> 0.83236771 | N40: =N31/N27 -> 0.80819497 | O40: =O31/O27 -> 0.80565598
B41: * Sem Equivalência Patrimonial
B43: DRE DEMERCADO (Em R$/Mil) | C43: =C3 -> JULHO | H43: =H3 -> ACUMULADO JANEIRO A JULHO | M43: =M23 -> RITMO
C44: Real 2025 | D44: Orç 2026 | E44: Real 2026 | F44: Real 2026 x Orç 2026 | G44: Real 2026 x Real 2025 | H44: Real 2025 | I44: Orç 2026 | J44: Real 2026 | K44: Real 2026 x Orç 2026 | L44: Real 2026 x Real 2025 | M44: Real 2025 | N44: Orç 2026 | O44: Ritmo 2026 | P44: Ritmo 2026 x Orç 2026 | Q44: Ritmo 2026 x Real 2025
B45: 1 - FATURAMENTO BRUTO | C45: =C25 -> 2564.2398 | D45: =D25 -> 3102.9476 | E45: =E25 -> 3145.0303 | F45: =IFERROR(E45/D45-1," ") -> 0.013562162 | G45: =IFERROR(E45/C45-1," ") -> 0.22649616 | H45: =H25 -> 15234.411 | I45: =I25 -> 17868.539 | J45: =J25 -> 18096.707 | K45: =IFERROR(J45/I45-1," ") -> 0.012769262 | L45: =IFERROR(J45/H45-1," ") -> 0.1878836 | M45: =M25 -> 31012.395 | N45: =N25 -> 36865.671 | O45: =O25 -> 37487.177 | P45: =IFERROR(O45/N45-1," ") -> 0.01685866 | Q45: =IFERROR(O45/M45-1," ") -> 0.20878047
...

Sheet DCL_D-ESPAÇO 
B2: DRE DCL - SHOPPING CENTER (Em R$/Mil) | C2: JUNHO | H2: ACUMULADO JANEIRO A JUNHO | M2: RITMO
C3: Real 2025 | D3: Orç 2026 | E3: Real 2026 | F3: Real 2026 x Orç 2026 | G3: Real 2026 x Real 2025 | H3: Real 2025 | I3: Orç 2026 | J3: Real 2026 | K3: Real 2026 x Orç 2026 | L3: Real 2026 x Real 2025 | M3: Real 2025 | N3: Orç 2026 | O3: Ritmo 2026 | P3: Ritmo 2026 x Orç 2026 | Q3: Ritmo 2026 x Real 2025
B4: 1 - FATURAMENTO BRUTO | C4: ='DRE DCL E D-ESPAÇO'!B4/1000 -> 929.60876 | D4: ='DRE DCL E D-ESPAÇO'!C4/1000 -> 1174.4612 | E4: ='DRE DCL E D-ESPAÇO'!D4/1000 -> 1189.405 | F4: =IFERROR(E4/D4-1," ") -> 0.012723954 | G4: =IFERROR(E4/C4-1," ") -> 0.27946834 | H4: ='DRE DCL E D-ESPAÇO'!H4/1000 -> 5653.6086 | I4: ='DRE DCL E D-ESPAÇO'!I4/1000 -> 6676.4325 | J4: ='DRE DCL E D-ESPAÇO'!J4/1000 -> 7037.3068 | K4: =IFERROR(J4/I4-1," ") -> 0.054051981 | L4: =IFERROR(J4/H4-1," ") -> 0.24474603 | M4: ='DRE DCL E D-ESPAÇO'!N4/1000 -> 12163.891 | N4: ='DRE DCL E D-ESPAÇO'!O4/1000 -> 13536.552 | O4: ='DRE DCL E D-ESPAÇO'!P4/1000 -> 14158.809 | P4: =IFERROR(O4/N4-1," ") -> 0.045968653 | Q4: =IFERROR(O4/M4-1," ") -> 0.16400332
B5: 2 - DEDUÇÃO DE FATURAMENTO | C5: =-'DRE DCL E D-ESPAÇO'!B5/1000 -> -51.48516 | D5: =-'DRE DCL E D-ESPAÇO'!C5/1000 -> -74.83227 | E5: =-'DRE DCL E D-ESPAÇO'!D5/1000 -> -62.78813 | F5: =IFERROR(E5/D5-1," ") -> -0.16094848 | G5: =IFERROR(E5/C5-1," ") -> 0.21953841 | H5: =-'DRE DCL E D-ESPAÇO'!H5/1000 -> -323.6601 | I5: =-'DRE DCL E D-ESPAÇO'!I5/1000 -> -430.04734 | J5: =-'DRE DCL E D-ESPAÇO'!J5/1000 -> -509.34007 | K5: =IFERROR(J5/I5-1," ") -> 0.1843814 | L5: =IFERROR(J5/H5-1," ") -> 0.57368817 | M5: =-'DRE DCL E D-ESPAÇO'!N5/1000 -> -799.44911 | N5: =-'DRE DCL E D-ESPAÇO'!O5/1000 -> -879.06409 | O5: =-'DRE DCL E D-ESPAÇO'!P5/1000 -> -945.916 | P5: =IFERROR(O5/N5-1," ") -> 0.07604896 | Q5: =IFERROR(O5/M5-1," ") -> 0.18320977
B6: 3 - FATURAMENTO LÍQUIDO | C6: =C4+C5 -> 878.1236 | D6: =D4+D5 -> 1099.6289 | E6: =E4+E5 -> 1126.6169 | F6: =IFERROR(E6/D6-1," ") -> 0.024542761 | G6: =IFERROR(E6/C6-1," ") -> 0.28298209 | H6: =H4+H5 -> 5329.9485 | I6: =I4+I5 -> 6246.3851 | J6: =J4+J5 -> 6527.9668 | K6: =IFERROR(J6/I6-1," ") -> 0.04507914 | L6: =IFERROR(J6/H6-1," ") -> 0.22477108 | M6: =M4+M5 -> 11364.441 | N6: =N4+N5 -> 12657.488 | O6: =O4+O5 -> 13212.893 | P6: =IFERROR(O6/N6-1," ") -> 0.043879572 | Q6: =IFERROR(O6/M6-1," ") -> 0.16265221
B7: 4 - CUSTO MERCADORIA VENDIDA | C7: 0 | D7: 0 | E7: 0 | F7: 0 | G7: 0 | H7: 0 | I7: 0 | J7: 0 | K7: 0 | L7: 0 | M7: 0 | N7: 0 | O7: 0 | P7: 0 | Q7: 0
B8: 5 - LUCRO BRUTO | C8: =C6+C7 -> 878.1236 | D8: =D6+D7 -> 1099.6289 | E8: =E6+E7 -> 1126.6169 | F8: =IFERROR(E8/D8-1," ") -> 0.024542761 | G8: =IFERROR(E8/C8-1," ") -> 0.28298209 | H8: =H6 -> 5329.9485 | I8: =I6 -> 6246.3851 | J8: =J6 -> 6527.9668 | K8: =IFERROR(J8/I8-1," ") -> 0.04507914 | L8: =IFERROR(J8/H8-1," ") -> 0.22477108 | M8: =M6+M7 -> 11364.441 | N8: =N6+N7 -> 12657.488 | O8: =O6+O7 -> 13212.893 | P8: =IFERROR(O8/N8-1," ") -> 0.043879572 | Q8: =IFERROR(O8/M8-1," ") -> 0.16265221
B9: 6 - DESPESAS OPERACIONAIS | C9: =-'DRE DCL E D-ESPAÇO'!B7/1000+'DRE DCL E D-ESPAÇO'!B11/1000 -> -418.40528 | D9: =-'DRE DCL E D-ESPAÇO'!C7/1000+'DRE DCL E D-ESPAÇO'!C11/1000 -> -436.56753 | E9: =-'DRE DCL E D-ESPAÇO'!D7/1000+'DRE DCL E D-ESPAÇO'!D11/1000 -> -353.18054 | F9: =IFERROR(E9/D9-1," ") -> -0.19100594 | G9: =IFERROR(E9/C9-1," ") -> -0.1558889 | H9: =-'DRE DCL E D-ESPAÇO'!H7/1000+'DRE DCL E D-ESPAÇO'!H11/1000 -> -2163.8498 | I9: =-'DRE DCL E D-ESPAÇO'!I7/1000+'DRE DCL E D-ESPAÇO'!I11/1000 -> -2686.0201 | J9: =-'DRE DCL E D-ESPAÇO'!J7/1000+'DRE DCL E D-ESPAÇO'!J11/1000 -> -2258.5453 | K9: =IFERROR(J9/I9-1," ") -> -0.159148 | L9: =IFERROR(J9/H9-1," ") -> 0.04376251 | M9: =-'DRE DCL E D-ESPAÇO'!N7/1000+'DRE DCL E D-ESPAÇO'!N11/1000 -> -4444.1877 | N9: =-'DRE DCL E D-ESPAÇO'!O7/1000+'DRE DCL E D-ESPAÇO'!O11/1000+0.6 -> -5191.1278 | O9: =-'DRE DCL E D-ESPAÇO'!P7/1000+'DRE DCL E D-ESPAÇO'!P11/1000 -> -4570.001 | P9: =IFERROR(O9/N9-1," ") -> -0.11965161 | Q9: =IFERROR(O9/M9-1," ") -> 0.028309637
B10: 7 - EBITDA | C10: =C8+C9 -> 459.71832 | D10: =D8+D9 -> 663.06139 | E10: =E8+E9 -> 773.43631 | F10: =IFERROR(E10/D10-1," ") -> 0.1664626 | G10: =IFERROR(E10/C10-1," ") -> 0.6824135 | H10: =H8+H9 -> 3166.0986 | I10: =I8+I9 -> 3560.365 | J10: =J8+J9 -> 4269.4214 | K10: =IFERROR(J10/I10-1," ") -> 0.19915272 | L10: =IFERROR(J10/H10-1," ") -> 0.34848023 | M10: =M8+M9 -> 6920.2538 | N10: =N8+N9 -> 7466.3601 | O10: =O8+O9 -> 8642.892 | P10: =IFERROR(O10/N10-1," ") -> 0.15757771 | Q10: =IFERROR(O10/M10-1," ") -> 0.24892703
B11: 8 - DEPRECIAÇÃO | C11: =-'DRE DCL E D-ESPAÇO'!B9/1000 -> -89.33857 | D11: =-'DRE DCL E D-ESPAÇO'!C9/1000 -> -107.87608 | E11: =-'DRE DCL E D-ESPAÇO'!D9/1000 -> -109.47557 | F11: =IFERROR(E11/D11-1," ") -> 0.014827105 | G11: =IFERROR(E11/C11-1," ") -> 0.22540097 | H11: =-'DRE DCL E D-ESPAÇO'!H9/1000 -> -533.01363 | I11: =-'DRE DCL E D-ESPAÇO'!I9/1000 -> -640.38748 | J11: =-'DRE DCL E D-ESPAÇO'!J9/1000 -> -644.1836 | K11: =IFERROR(J11/I11-1," ") -> 0.0059278486 | L11: =IFERROR(J11/H11-1," ") -> 0.20856872 | M11: =-'DRE DCL E D-ESPAÇO'!N9/1000 -> -1109.9689 | N11: =-'DRE DCL E D-ESPAÇO'!O9/1000 -> -1313.136 | O11: =-'DRE DCL E D-ESPAÇO'!P9/1000 -> -1276.077 | P11: =IFERROR(O11/N11-1," ") -> -0.028221738 | Q11: =IFERROR(O11/M11-1," ") -> 0.14965116
B12: 9 - RESULTADO OPERACIONAL | C12: =C10+C11 -> 370.37975 | D12: =D10+D11 -> 555.18531 | E12: =E10+E11 -> 663.96074 | F12: =IFERROR(E12/D12-1," ") -> 0.19592635 | G12: =IFERROR(E12/C12-1," ") -> 0.7926486 | H12: =H10+H11 -> 2633.085 | I12: =I10+I11 -> 2919.9776 | J12: =J10+J11 -> 3625.2378 | K12: =IFERROR(J12/I12-1," ") -> 0.24152935 | L12: =IFERROR(J12/H12-1," ") -> 0.37680243 | M12: =M10+M11 -> 5810.2849 | N12: =N10+N11-1 -> 6152.2241 | O12: =O10+O11 -> 7366.815 | P12: =IFERROR(O12/N12-1," ") -> 0.19742306 | Q12: =IFERROR(O12/M12-1," ") -> 0.26789221
B13: 10 - OUTRAS RECEITAS E DESPESAS | C13: =C14+C15 -> -43.47349 | D13: =D14+D15 -> -106.56121 | E13: =E14+E15 -> -63.31012 | F13: =IFERROR(E13/D13-1," ") -> -0.40588024 | G13: =IFERROR(E13/C13-1," ") -> 0.45629256 | H13: =H14+H15 -> -263.89106 | I13: =I14+I15 -> -661.15789 | J13: =J14+J15 -> -469.36039 | K13: =IFERROR(J13/I13-1," ") -> -0.29009334 | L13: =IFERROR(J13/H13-1," ") -> 0.77861421 | M13: =M14+M15 -> -853.32875 | N13: =N14+N15 -> -1291.1199 | O13: =O14+O15 -> -1035.8937 | P13: =IFERROR(O13/N13-1," ") -> -0.19767817 | Q13: =IFERROR(O13/M13-1," ") -> 0.21394446
B14: 10.1 - RECEITAS FINANCEIRAS | C14: ='DRE DCL E D-ESPAÇO'!B13/1000 -> 4.72904 | D14: ='DRE DCL E D-ESPAÇO'!C13/1000 -> 11.71742 | E14: ='DRE DCL E D-ESPAÇO'!D13/1000 -> 51.68424 | F14: =IFERROR(E14/D14-1," ") -> 3.4108891 | G14: =IFERROR(E14/C14-1," ") -> 9.9291188 | H14: ='DRE DCL E D-ESPAÇO'!H13/1000 -> 59.21248 | I14: ='DRE DCL E D-ESPAÇO'!I13/1000 -> 65.50501 | J14: ='DRE DCL E D-ESPAÇO'!J13/1000 -> 219.61504 | K14: =IFERROR(J14/I14-1," ") -> 2.3526449 | L14: =IFERROR(J14/H14-1," ") -> 2.7089316 | M14: ='DRE DCL E D-ESPAÇO'!N13/1000 -> 184.39723 | N14: ='DRE DCL E D-ESPAÇO'!O13/1000 -> 111.13091 | O14: ='DRE DCL E D-ESPAÇO'!P13/1000 -> 335.58523 | P14: =IFERROR(O14/N14-1," ") -> 2.019729 | Q14: =IFERROR(O14/M14-1," ") -> 0.81990386
B15: 10.2 - DESPESAS FINANCEIRAS | C15: =-'DRE DCL E D-ESPAÇO'!B14/1000 -> -48.20253 | D15: =-'DRE DCL E D-ESPAÇO'!C14/1000 -> -118.27863 | E15: =-'DRE DCL E D-ESPAÇO'!D14/1000 -> -114.99436 | F15: =IFERROR(E15/D15-1," ") -> -0.027767231 | G15: =IFERROR(E15/C15-1," ") -> 1.3856499 | H15: =-'DRE DCL E D-ESPAÇO'!H14/1000 -> -323.10354 | I15: =-'DRE DCL E D-ESPAÇO'!I14/1000 -> -726.6629 | J15: =-'DRE DCL E D-ESPAÇO'!J14/1000 -> -688.97543 | K15: =IFERROR(J15/I15-1," ") -> -0.05186376 | L15: =IFERROR(J15/H15-1," ") -> 1.1323673 | M15: =-'DRE DCL E D-ESPAÇO'!N14/1000 -> -1037.726 | N15: =-'DRE DCL E D-ESPAÇO'!O14/1000 -> -1402.2508 | O15: =-'DRE DCL E D-ESPAÇO'!P14/1000 -> -1371.4789 | P15: =IFERROR(O15/N15-1," ") -> -0.021944654 | Q15: =IFERROR(O15/M15-1," ") -> 0.32161955
B16: 11 - LUCRO ANTES DO IR/CSLL | C16: =C12+C13 -> 326.90626 | D16: =D12+D13 -> 448.6241 | E16: =E12+E13 -> 600.65062 | F16: =IFERROR(E16/D16-1," ") -> 0.33887283 | G16: =IFERROR(E16/C16-1," ") -> 0.83737876 | H16: =H12+H13 -> 2369.194 | I16: =I12+I13 -> 2258.8197 | J16: =J12+J13 -> 3155.8775 | K16: =IFERROR(J16/I16-1," ") -> 0.39713563 | L16: =IFERROR(J16/H16-1," ") -> 0.3320469 | M16: =M12+M13 -> 4956.9562 | N16: =N12+N13 -> 4861.1041 | O16: =O12+O13 -> 6330.9213 | P16: =IFERROR(O16/N16-1," ") -> 0.30236282 | Q16: =IFERROR(O16/M16-1," ") -> 0.27717919
B17: 12 - IR/CSLL | C17: =-'DRE DCL E D-ESPAÇO'!B16/1000 -> -99.92697 | D17: =-'DRE DCL E D-ESPAÇO'!C16/1000 -> -127.833 | E17: =-'DRE DCL E D-ESPAÇO'!D16/1000 -> -152.66363 | F17: =IFERROR(E17/D17-1," ") -> 0.19424272 | G17: =IFERROR(E17/C17-1," ") -> 0.52775202 | H17: =-'DRE DCL E D-ESPAÇO'!H16/1000 -> -618.35955 | I17: =-'DRE DCL E D-ESPAÇO'!I16/1000 -> -769.64207 | J17: =-'DRE DCL E D-ESPAÇO'!J16/1000 -> -850.70292 | K17: =IFERROR(J17/I17-1," ") -> 0.10532279 | L17: =IFERROR(J17/H17-1," ") -> 0.37574154 | M17: =-'DRE DCL E D-ESPAÇO'!N16/1000 -> -1340.7368 | N17: =-'DRE DCL E D-ESPAÇO'!O16/1000 -> -1462.0052 | O17: =-'DRE DCL E D-ESPAÇO'!P16/1000 -> -1691.415 | P17: =IFERROR(O17/N17-1," ") -> 0.15691447 | Q17: =IFERROR(O17/M17-1," ") -> 0.26155634
B18: 13 - LUCRO LÍQUIDO | C18: =C16+C17 -> 226.97929 | D18: =D16+D17 -> 320.7911 | E18: =E16+E17 -> 447.98699 | F18: =IFERROR(E18/D18-1," ") -> 0.39650692 | G18: =IFERROR(E18/C18-1," ") -> 0.97369104 | H18: =H16+H17 -> 1750.8344 | I18: =I16+I17 -> 1489.1776 | J18: =J16+J17 -> 2305.1745 | K18: =IFERROR(J18/I18-1," ") -> 0.54795138 | L18: =IFERROR(J18/H18-1," ") -> 0.31661482 | M18: =M16+M17 -> 3616.2194 | N18: =N16+N17 -> 3399.0989 | O18: =O16+O17 -> 4639.5063 | P18: =IFERROR(O18/N18-1," ") -> 0.36492241 | Q18: =IFERROR(O18/M18-1," ") -> 0.28297147
B19: Margem EBITDA/ROL | C19: =C10/C6 -> 0.52352348 | D19: =D10/D6 -> 0.6029865 | E19: =E10/E6 -> 0.68651229 | H19: =H10/H6 -> 0.5940205 | I19: =I10/I6 -> 0.56998808 | J19: =J10/J6 -> 0.65402009 | M19: =M10/M6 -> 0.60893919 | N19: =N10/N6 -> 0.58987693 | O19: =O10/O6 -> 0.65412563
B22: DRE D-ESPAÇO (Em R$/Mil) | C22: JUNHO | H22: ACUMULADO JANEIRO A JUNHO | M22: RITMO
C23: Real 2025 | D23: Orç 2026 | E23: Real 2026 | F23: Real 2026 x Orç 2026 | G23: Real 2026 x Real 2025 | H23: Real 2025 | I23: Orç 2026 | J23: Real 2026 | K23: Real 2026 x Orç 2026 | L23: Real 2026 x Real 2025 | M23: Real 2025 | N23: Orç 2026 | O23: Ritmo 2026 | P23: Ritmo 2026 x Orç 2026 | Q23: Ritmo 2026 x Real 2025
B24: 1 - FATURAMENTO BRUTO | C24: ='DRE DCL E D-ESPAÇO'!B23/1000 -> 196.49505 | D24: ='DRE DCL E D-ESPAÇO'!C23/1000 -> 208.34797 | E24: ='DRE DCL E D-ESPAÇO'!D23/1000 -> 222.85259 | F24: =IFERROR(E24/D24-1," ") -> 0.069617285 | G24: =IFERROR(E24/C24-1," ") -> 0.13413844 | H24: ='DRE DCL E D-ESPAÇO'!H23/1000 -> 1164.6683 | I24: ='DRE DCL E D-ESPAÇO'!I23/1000 -> 1248.6041 | J24: ='DRE DCL E D-ESPAÇO'!J23/1000 -> 1294.6718 | K24: =IFERROR(J24/I24-1," ") -> 0.036895338 | L24: =IFERROR(J24/H24-1," ") -> 0.11162272 | M24: ='DRE DCL E D-ESPAÇO'!N23/1000 -> 2393.6629 | N24: ='DRE DCL E D-ESPAÇO'!O23/1000 -> 2504.9619 | O24: ='DRE DCL E D-ESPAÇO'!P23/1000 -> 2585.272 | P24: =IFERROR(O24/N24-1," ") -> 0.032060412 | Q24: =IFERROR(O24/M24-1," ") -> 0.080048494
B25: 2 - DEDUÇÃO DE FATURAMENTO | C25: =-'DRE DCL E D-ESPAÇO'!B24/1000 -> -7.17207 | D25: =-'DRE DCL E D-ESPAÇO'!C24/1000 -> -7.6047 | E25: =-'DRE DCL E D-ESPAÇO'!D24/1000 -> -8.13412 | F25: =IFERROR(E25/D25-1," ") -> 0.069617473 | G25: =IFERROR(E25/C25-1," ") -> 0.1341384 | H25: =-'DRE DCL E D-ESPAÇO'!H24/1000 -> -42.91042 | I25: =-'DRE DCL E D-ESPAÇO'!I24/1000 -> -45.57404 | J25: =-'DRE DCL E D-ESPAÇO'!J24/1000 -> -48.36533 | K25: =IFERROR(J25/I25-1," ") -> 0.061247368 | L25: =IFERROR(J25/H25-1," ") -> 0.1271232 | M25: =-'DRE DCL E D-ESPAÇO'!N24/1000 -> -88.6281 | N25: =-'DRE DCL E D-ESPAÇO'!O24/1000 -> -91.4311 | O25: =-'DRE DCL E D-ESPAÇO'!P24/1000 -> -95.472 | P25: =IFERROR(O25/N25-1," ") -> 0.044196121 | Q25: =IFERROR(O25/M25-1," ") -> 0.07722043
