Workbook

Sheet Comparação
A1: Manutenção de imóveis — Mega Esteio · itens do Orç 2026 × Orç 2027
A2: Preencha a coluna COMPARA? com SIM ou NÃO nas linhas amarelas (dúvidas). As outras já vêm com a leitura da análise e podem ser trocadas. Só os pares com SIM entram na comparação item a item da apresentação.
A3: Orç 2026: "MESTRA - ORÇAMENTO 2026 ITEM A ITEM" (centro de custo do condomínio) + "MESTRA - CONTRATOS 2026". Orç 2027: modelo 090 + "MESTRA - CONTRATOS 2027". Orç 2026: R$ 4.500 acima da METRAGEM-COND. Orç 2027: R$ 15.268 acima (as duas linhas de vida, out).
A5: # | B5: Tipo | C5: Item no Orç 2026 | D5: Orç 2026 | E5: Item(ns) no Orç 2027 | F5: Categoria 2027 | G5: Orç 2027 | H5: Δ R$ | I5: Leitura da análise | J5: Por quê | K5: COMPARA? | L5: Comentário do gestor
A6: 1 | B6: Avulso | C6: Manutenção nas juntas de dilatação contenção #14813862 | D6: 12964 | E6: MANUTENÇÃO DE JUNTA DILATAÇAÕ TERRAE AMRMAZÉM A (T1, T3 E T7) + MANUTENÇÃO DE JUNTA DILATAÇÃO TERRAE ARMAZÉM B (T5 E T6) | F6: CONTENÇÃO | G6: 23827.2 | H6: =G6-D6 -> 10863.2 | I6: Dúvida | J6: Juntas de dilatação da contenção nos dois anos (2027: taludes dos armazéns A e B). Continuação do serviço ou repetição? | K6: SIM | L6: Importante que base que usou para comparar é somente do A em 2026
A7: 2 | B7: Avulso | C7: Pacote serralheira *10917019 *12943732 | D7: 14000 | E7: COMPRA DE INSUMOS DE MATERIAIS DE CONSTRUÇÃO ZELADORIA | F7: INSUMOS | G7: 18000 | H7: =G7-D7 -> 4000 | I7: Dúvida | J7: Os dois são verba para pequenos reparos, mas um é serralheria e o outro material de construção para o zelador. | K7: NÃO | L7: São coisas diferentes
A8: 3 | B8: Avulso | C8: Substituir lona totem #14592624 | D8: 18000 | E8: SUBSTITUIÇÃO POR VIDA ÚTIL DA LONA DO MEGA (POSTO) | F8: PUBLICIDADE | G8: 15000 | H8: =G8-D8 -> -3000 | I8: Dúvida | J8: Troca de lona nos dois anos: 2026 a do totem, 2027 a do posto. É a mesma lona? | K8: SIM
A9: 4 | B9: Avulso | C9: Provisão reparo sistemas de acesso | D9: 16481.84 | E9: — | H9: =G9-D9 -> -16481.84 | I9: Dúvida | J9: Sem verba de acesso em 2027 (Curitiba e Itajaí passam a ter o contrato FM Security). Ficou de fora do orçamento? | K9: SIM | L9: Ficou fora... Mas a base de compraração será a linha de manutenções não previstas de 3%
A10: 5 | B10: Avulso | C10: Provisão gastos CFTV | D10: 10880 | E10: — | H10: =G10-D10 -> -10880 | I10: Dúvida | J10: Sem verba de CFTV em 2027 (ver a linha de cima). | L10: Ficou fora... Mas a base de compraração será a linha de manutenções não previstas de 3%
A11: 6 | B11: Avulso | C11: Juntas das placas nas paredes na fase 03 (fundos módulos 07 ao 11)#13890191 #13890216 | D11: 10330.75 | E11: MANUTENÇÃO DE JUNTA DE DILATAÇÃO ENTRE PLACAS DE FECHAMENTO (LATERAL M12) | F11: REVESTIMENTO | G11: 9000 | H11: =G11-D11 -> -1330.75 | I11: Dúvida | J11: Juntas das placas de fechamento nos dois anos: 2026 fundos dos módulos 07 a 11; 2027 lateral M12. Mesmo serviço em outra parede? | K11: SIM | L11: Compara, mas são áreas diferentes.
A12: 7 | B12: Avulso | C12: Preventiva bombas de drenagem | D12: 6300 | E12: MANUTENÇÃO PREVENTIVA ANUAL DA COMPORTA AMZ A + MANUTENÇÃO PREVENTIVA ANUAL DA COMPORTA AMZ B | F12: HIDRÁULICA | G12: 8838 | H12: =G12-D12 -> 2538 | I12: Dúvida | J12: 2026: preventiva das bombas de drenagem; 2027: preventiva das comportas (A e B). Mesmo sistema? | K12: SIM
A13: 8 | B13: Avulso | C13: Peças para painéis elétricos (substituir disjuntores e contatoras do sinistro) | D13: 8335 | E13: VERBA PARA MANUTENÇÃO DE COMPONENTES NOS QUADROS (ELEVATÓRIAS) | F13: ELÉTRICA | G13: 2400 | H13: =G13-D13 -> -5935 | I13: Dúvida | J13: 2026: peças para os painéis (sinistro); 2027: verba para componentes dos quadros das elevatórias. Mesma verba? | K13: NÃO
A14: 9 | B14: Contrato | C14: CONTRATO — ADS MANUTENÇÃO PREDIAL | D14: 45496.21 | E14: CONTRATO — ADS MANUTENÇÃO PREDIAL + ADITIVO CONTRATO MANUTENÇÃO COBERTURA NO B1 | F14: COBERTURA | G14: 124271.82 | H14: =G14-D14 -> 78775.61 | I14: Compara | J14: Mesmo contrato de cobertura, com aditivo para o B1 em 2027. | K14: SIM
A15: 10 | B15: Contrato | C15: CONTRATO — ARC SOLUÇÕES NO COMBATE A INCENDIO | D15: 74184.53 | E15: ALTERAÇÃO DO CONTRATO SDAI (RESCISÃO ARC) - ARMAZÉM A E B | F15: PPCI | G15: 90743.52 | H15: =G15-D15 -> 16558.99 | I15: Compara | J15: Mesmo serviço (SDAI): o contrato da ARC foi rescindido e entra um novo em 2027 (+22%). | K15: SIM
A16: 11 | B16: Contrato | C16: CONTRATO — Subestação Energia | D16: 15102.87 | E16: CONTRATO — Subestação Energia | F16: ELÉTRICA | G16: 66821.04 | H16: =G16-D16 -> 51718.17 | I16: Compara | J16: Mesmo contrato (subestação). Sobe de R$ 15 mil para R$ 67 mil: confirmar se 2026 teve só parte do ano. | K16: SIM | L16: Em 2027 entra o Armazém B1 e B2
A17: 12 | B17: Avulso | C17: Preventiva/Limpeza das elevatórias | D17: 14666.67 | E17: SUCCÇÃO E LIMPEZA SEMESTRAL DAS ELEVATÓRIAS (ARMAZÉM A E B) | F17: HIDROSSANITÁRIO | G17: 43792.84 | H17: =G17-D17 -> 29126.17 | I17: Compara | J17: Mesmo serviço: limpeza das elevatórias. Triplica em 2027 (semestral, armazéns A e B). | K17: SIM | L17: Considerar unificação dos Armazéns... Entra B1 e B2 e deixa de ser anual e passa a ser semestral
A18: 13 | B18: Avulso | C18: Laudo linha de vida | D18: 6500 | E18: LAUDO DE LINHA DE VIDA ARMAZÉM A - ALPENDRE + LAUDO DE LINHA DE VIDA ARMAZÉM A - COBERTURA + LAUDO DE LINHA DE VIDA ARMAZÉM B2 - ALPENDRE + LAUDO DE LINHA DE VIDA ARMAZÉM B2 - COBERTURA DO DOCAS - 125M2 + LAUDO DE LINHA DE VIDA ARMAZÉM B2 - COBERTURA ARMAZÉM 400M2 | F18: SCPQ | G18: 32500 | H18: =G18-D18 -> 26000 | I18: Compara | J18: Mesmo serviço; em 2027 são cinco laudos (um por cobertura e alpendre). | K18: SIM | L18: Correto. São 5 lihas de vida a serem laudadas
A19: 14 | B19: Avulso | C19: Provisão manutenções emergências | D19: 31200 | E19: PROVISÃO DE 3% SOBRE A MANUTENÇÃO PARA ITENS NÃO PREVISTOS | F19: MANUTENÇÃO EMERGENCIAL | G19: 20803.32 | H19: =G19-D19 -> -10396.68 | I19: Compara | J19: As duas são a reserva para o que não foi previsto (em 2027, 3% do pacote). | K19: SIM
A20: 15 | B20: Contrato | C20: CONTRATO — MANUTENÇÃO GERADOR | D20: 10266.24 | E20: CONTRATO — MANUTENÇÃO GERADOR | F20: ELÉTRICA | G20: 28252.56 | H20: =G20-D20 -> 17986.32 | I20: Compara | J20: Mesmo contrato (gerador). Sobe de R$ 10 mil para R$ 28 mil: confirmar se 2026 teve só parte do ano. | K20: SIM | L20: Em 2027 entra o Armazém B1 e B2
A21: 16 | B21: Avulso | C21: Preventiva Limpeza fossas | D21: 15900 | E21: SUCÇÃO E LIMPEZA DO STE (SEMESTRAL) - FOSSA E FILTRO - ARMAZÉM A + SUCÇÃO E LIMPEZA DO STE (SEMESTRAL) - FOSSA E FILTRO - ARMAZÉM B | F21: HIDROSSANITÁRIO | G21: 24014.31 | H21: =G21-D21 -> 8114.31 | I21: Compara | J21: Mesmo serviço: limpeza das fossas (STE), em 2027 aberta por armazém. | K21: SIM
A22: 17 | B22: Avulso | C22: Provisão para iluminação da área comum/manutenções elétricas | D22: 21832.26 | E22: VERBA PARA SUBSTITUIÇÃO DE LÂMPADAS NO CONDOMÍNIO | F22: ELÉTRICA | G22: 6000 | H22: =G22-D22 -> -15832.26 | I22: Compara | J22: As duas são verba para a iluminação da área comum. | K22: SIM
A23: 18 | B23: Avulso | C23: Preventiva/PAE Brigada/ extintores | D23: 6000 | E23: TREINAMENTO ANUAL DE BRIGADA DE INCÊNDIO DO ARMAZÉM A + RENOVAÇÃO DO PLANO DE EMERGÊNCIA DO ARMAZÉM A COM ART + RENOVAÇÃO DO PLANO DE EMERGÊNCIA DO ARMAZÉM B COM ART + RENOVAÇÃO DE CARGA DE EXTINTORES E LAUDO HIDROSTÁTICO DE MANGUEIRAS | F23: PPCI | G23: 14110 | H23: =G23-D23 -> 8110 | I23: Compara | J23: Em 2026 era um item só; em 2027 virou quatro (brigada, PAE dos dois armazéns e extintores). | K23: SIM
A24: 19 | B24: Avulso | C24: Preventiva condicionadores de ar | D24: 3200 | E24: REVISÃO E MANUTENÇÃO DOS ARES CONDICIONADOS CONFORME PMOC | F24: MANUTENÇÃO PREVENTIVA | G24: 7700 | H24: =G24-D24 -> 4500 | I24: Compara | J24: Mesmo serviço (preventiva PMOC); mais que dobra em 2027. | K24: SIM | L24: Adequação do contrato para premissa do PMOC (aumento de inspeções e manutenções)
A25: 20 | B25: Avulso | C25: Provisão para demarcação de pátio | D25: 5000 | E25: RENOVAÇÃO DE DEMARCAÇÃO SEMESTRAL ENTRADA (PORTARIA A E B) - SOMENTE MATERIAL + RENOVAÇÃO DE DEMERCAÇÃO ANUAL FRENTE DE DOCAS (FAIXAS) - SOMENTE MATERIAL | F25: SINALIZAÇÃO VIÁRIA | G25: 7668.63 | H25: =G25-D25 -> 2668.63 | I25: Compara | J25: Mesmo serviço: demarcação do pátio, em 2027 aberta por área. | K25: SIM
A26: 21 | B26: Avulso | C26: Renovação SPDA | D26: 2968 | E26: MEDIÇÕES, AFERIÇÕES E LAUDO DO SPDA (ARMAZÉM A E B) | F26: ELÉTRICA | G26: 5400 | H26: =G26-D26 -> 2432 | I26: Compara | J26: Mesmo serviço: laudo do SPDA. | K26: SIM
A27: 22 | B27: Avulso | C27: Rota de Fuga | D27: 119434.1 | E27: — | H27: =G27-D27 -> -119434.1 | I27: Não compara | J27: Obra pontual de 2026. | K27: NÃO
A28: 23 | B28: Avulso | C28: Pintura total do reservatório 02 #14527327 | D28: 56585 | E28: MANUTENÇÃO DA ESTRUTURA METÁLICA DO RESERVATÓRIO B2 | F28: RESERVATÓRIO | G28: 1 | H28: =G28-D28 -> -56584 | I28: Não compara | J28: Pintura pontual de 2026; em 2027 o reservatório B2 está com R$ 1 (retirado). | K28: NÃO
A29: 24 | B29: Avulso | C29: Cabeçote, juntas e pistões/ trator 2 #14745887 | D29: 25435.9 | E29: — | H29: =G29-D29 -> -25435.9 | I29: Não compara | J29: Trator: em 2027 os tratores não estão na manutenção de imóveis (ver Manutenção de máquinas e equipamentos, R$ 146 mil). | K29: NÃO | L29: Foi pontual
A30: 25 | B30: Avulso | C30: Escada para acesso espaço lazer *6046204 | D30: 14000 | E30: — | H30: =G30-D30 -> -14000 | I30: Não compara | J30: Obra pontual de 2026. | K30: NÃO
A31: 26 | B31: Avulso | C31: Preventiva tratores | D31: 13993.59 | E31: — | H31: =G31-D31 -> -13993.59 | I31: Não compara | J31: Trator: em 2027 os tratores não estão na manutenção de imóveis (ver Manutenção de máquinas e equipamentos). | K31: SIM | L31: Compara, mas está em linha separada... Entra em Manutençoes de Bens Móveis
A32: 27 | B32: Avulso | C32: Manutenção elétrica trator 01 (substituição dos chicotes) #14592319 | D32: 11915.96 | E32: — | H32: =G32-D32 -> -11915.96 | I32: Não compara | J32: Trator: em 2027 os tratores não estão na manutenção de imóveis (ver Manutenção de máquinas e equipamentos). | K32: NÃO | L32: Foi pontual
A33: 28 | B33: Avulso | C33: Provisão Manutenção corretiva tratores | D33: 10133.76 | E33: — | H33: =G33-D33 -> -10133.76 | I33: Não compara | J33: Trator: em 2027 os tratores não estão na manutenção de imóveis (ver Manutenção de máquinas e equipamentos). | K33: SIM | L33: Compara, mas está em linha separada... Entra em Manutençoes de Bens Móveis
A34: 29 | B34: Avulso | C34: Manutenção/revisão bomba tratores | D34: 10000 | E34: — | H34: =G34-D34 -> -10000 | I34: Não compara | J34: Trator: em 2027 os tratores não estão na manutenção de imóveis (ver Manutenção de máquinas e equipamentos). | K34: SIM | L34: Compara, mas está em linha separada... Entra em Manutençoes de Bens Móveis
A35: 30 | B35: Avulso | C35: Poste iluminação régua *13292798 | D35: 9000 | E35: — | H35: =G35-D35 -> -9000 | I35: Não compara | J35: Obra pontual de 2026. | K35: NÃO
A36: 31 | B36: Avulso | C36: Preventiva - Av. Standard (drenagem) - Limpeza de caixas de passagem e hidrojateamento | D36: 6500 | E36: LIMPEZA E DESASSOREAMENTO PERIÓDICO NAS CAIXAS DE PASSAGEM - ARMAZÉM A | F36: PLUVIAL | G36: 1 | H36: =G36-D36 -> -6499 | I36: Não compara | J36: Em 2027 o item existe com R$ 1 (retirado do orçamento). | K36: NÃO
A37: 32 | B37: Avulso | C37: Equipamentos Espaço Lazer #10337495 | D37: 5400 | E37: — | H37: =G37-D37 -> -5400 | I37: Não compara | J37: Compra pontual de 2026. | K37: NÃO
A38: 33 | B38: Avulso | C38: Preventiva PPCI/bomba SPK | D38: 2650 | E38: REVISÃO ANUAL DA BOMBA DE SPK - ARMAZÉM A - RETIRADO DO ORÇAMENTO + REVISÃO ANUAL DA BOMBA DE SPK - ARMAZÉM B1 E B2 - RETIRADO DO ORÇAMENTO | F38: PPCI | G38: 2 | H38: =G38-D38 -> -2648 | I38: Não compara | J38: Em 2027 os itens existem com R$ 1 (retirados do orçamento). | K38: SIM | L38: Compara, mas está em linha separada... Entra em Manutençoes de Bens Móveis
A39: 34 | B39: Avulso | C39: Compra de ar condicionado #14596535 | D39: 2500 | E39: — | H39: =G39-D39 -> -2500 | I39: Não compara | J39: Compra pontual de 2026. | K39: NÃO
A40: 35 | B40: Avulso | C40: Provisão de Manutenção corretivas bombas de drenagem | D40: 29232.69 | E40: — | H40: =G40-D40 -> -29232.69 | I40: Só 2026 | J40: Sem item parecido em 2027. | K40: SIM | L40: Comprar com os 3% de manutenções não previstas em 2027
A41: 36 | B41: Avulso | C41: Provisão gastos PPCI | D41: 14311.92 | E41: — | H41: =G41-D41 -> -14311.92 | I41: Só 2026 | J41: Sem item parecido em 2027. | K41: SIM | L41: Comprar com os 3% de manutenções não previstas em 2027
...

Sheet Resumo
A1: Resumo da comparação (atualiza sozinho com as marcações)
A3: Total Orç 2026 (R$) | B3: =SUM('Comparação'!D6:D1000) -> 716495.27
A4: Total Orç 2027 (R$) | B4: =SUM('Comparação'!G6:G1000) -> 863046.99
A5: Itens marcados SIM — Orç 2026 (R$) | B5: =SUMIFS('Comparação'!D6:D1000,'Comparação'!K6:K1000,"SIM") -> 432509.31
A6: Itens marcados SIM — Orç 2027 (R$) | B6: =SUMIFS('Comparação'!G6:G1000,'Comparação'!K6:K1000,"SIM") -> 528745.24
A7: Variação dos itens que comparam (R$) | B7: =B6-B5 -> 96235.93
A8: Variação dos itens que comparam (%) | B8: =IF(B5=0,0,B6/B5-1) -> 0.22250603
A9: Pares marcados SIM | B9: =COUNTIF('Comparação'!K6:K1000,"SIM") -> 29
A10: Dúvidas ainda sem resposta | B10: =COUNTIFS('Comparação'!I6:I1000,"Dúvida",'Comparação'!K6:K1000,"") -> 1
A12: Fonte: aba Comparação (Mega Esteio; Orç 2026 = mestras de 2026; Orç 2027 = modelo 090 + "MESTRA - CONTRATOS 2027").
